Workbook

Sheet Cover
C3: Oil and Gas Exploration & Production Company Analysis and Valuation
C6: Table of Contents
C7: 1 | D7: Dashboard
C8: =C7+1 -> 2 | D8: Historical Financials
C9: =C8+1 -> 3 | D9: Production & Reserves
C10: =C9+1 -> 4 | D10: Capital Structure
C11: =C10+1 -> 5 | D11: Debt Schedule
C12: =C11+1 -> 6 | D12: Forcast Model
C13: =C12+1 -> 7 | D13: NAV & Valuation
C14: =C13+1 -> 8 | D14: Notes

Sheet Historical Financials
B3: Financials
B6: Income Statement
F8: 2021 | G8: 2022 | H8: 2023 | I8: 2024 | J8: 2025
B9: Revenue:
B10: Natural Gas | F10: 31708185 | G10: 56948734 | H10: 14864214 | I10: 10786068 | J10: 29121446
B11: Natural Gas Liquids | F11: 1053486 | G11: 1733130 | H11: 984418 | I11: 1481958 | J11: 1978860
B12: Oil and Condensates | F12: 1776496 | G12: 3195333 | H12: 5090589 | I12: 13730686 | J12: 13803515
B13: Gathering and Compression | F13: 7865825 | G13: 8085512 | H13: 9790531 | I13: 5524063 | J13: 6683735
B14: Total Revenue | F14: =SUM(F10:F13) -> 42403992 | G14: =SUM(G10:G13) -> 69962709 | H14: =SUM(H10:H13) -> 30729752 | I14: =SUM(I10:I13) -> 31522775 | J14: =SUM(J10:J13) -> 51587556
B16: Operating Expenses:
B17: Lease Operating Expenses | F17: 7897738 | G17: 7128631 | H17: 6405281 | I17: 7264824 | J17: 12518325
B18: Gathering System Operating Expenses | F18: 726646 | G18: 2287763 | H18: 2459694 | I18: 2265190 | J18: 2362036
B19: Development of Geological and Geophysical Expenses | F19: 40299 | G19: 9545 | H19: 0 | I19: 0 | J19: 0
B20: DD&A | F20: 6627016 | G20: 6438511 | H20: 7685084 | I20: 10185119 | J20: 12170320
B21: Impairment Expense | F21: 153058 | G21: 0 | H21: 0 | I21: 1450076 | J21: 3936669
B22: Loss (Gain) on the Sale of Oil Properties | F22: -484902 | G22: -221642 | H22: 1449871 | I22: 0 | J22: 19256530
B23: Transaction Costs | F23: 0 | G23: 0 | H23: 0 | I23: 0 | J23: 2947907
B25: General and Administration:
B26: Stock Based Compensation Expense | F26: 956084 | G26: 1021026 | H26: 1018262 | I26: 1244416 | J26: 1744917
B27: Other General and Administration Expenses | F27: 5875732 | G27: 6325412 | H27: 6293234 | I27: 5688714 | J27: 7168235
B28: Total G&A | F28: =F26+F27 -> 6831816 | G28: =G26+G27 -> 7346438 | H28: =H26+H27 -> 7311496 | I28: =I26+I27 -> 6933130 | J28: =J26+J27 -> 8913152
B30: Total Operating Expenses | F30: =SUM(F17:F27) -> 21791671 | G30: =SUM(G17:G27) -> 22989246 | H30: =SUM(H17:H27) -> 25311426 | I30: =SUM(I17:I27) -> 28098339 | J30: =SUM(J17:J27) -> 62104939
B32: Operating Income (EBIT) | F32: =F14-F30 -> 20612321 | G32: =G14-G30 -> 46973463 | H32: =H14-H30 -> 5418326 | I32: =I14-I30 -> 3424436 | J32: =J14-J30 -> -10517383
B33: EBITDA | F33: =F32+F20 -> 27239337 | G33: =G32+G20 -> 53411974 | H33: =H32+H20 -> 13103410 | I33: =I32+I20 -> 13609555 | J33: =J32+J20 -> 1652937
B34: EBITDAX | F34: =F33+F19 -> 27279636 | G34: =G33+G19 -> 53421519 | H34: =H33+H19 -> 13103410 | I34: =I33+I19 -> 13609555 | J34: =J33+J19 -> 1652937
B35: Adjusted EBITDA | F35: =F33+F22+F21+F23+F19 -> 26947792 | G35: =G33+G22+G21+G23+G19 -> 53199877 | H35: =H33+H22+H21+H23+H19 -> 14553281 | I35: =I33+I22+I21+I23+I19 -> 15059631 | J35: =J33+J22+J21+J23+J19 -> 27794043
B37: Other Income (Expense):
B38: Interest Income | F38: 38865 | G38: 452877 | H38: 1673241 | I38: 493277 | J38: 188369
B39: Interest Expense | F39: -101382 | G39: -50782 | H39: -80379 | I39: -46400 | J39: -624160
B40: Gain (Loss) On Derative Contracts, Net | F40: -4482909 | G40: 236077 | H40: 3130055 | I40: -391147 | J40: 5500486
B41: Other Income, Net | F41: 1130 | G41: -99469 | H41: 4357 | I41: 76727 | J41: 16556
B42: Total Other Income (Expense) | F42: =SUM(F38:F41) -> -4544296 | G42: =SUM(G38:G41) -> 538703 | H42: =SUM(H38:H41) -> 4727274 | I42: =SUM(I38:I41) -> 132457 | J42: =SUM(J38:J41) -> 5081251
B43: Net Income (Loss) Before Income Tax (EBT) | F43: =F42+F32 -> 16068025 | G43: =G42+G32 -> 47512166 | H43: =H42+H32 -> 10145600 | I43: =I42+I32 -> 3556893 | J43: =J42+J32 -> -5436132
B45: Income Tax (Benefit) Expense | F45: 4440508 | G45: 12157487 | H45: 3200447 | I45: 1629093 | J45: 362731
B46: Net Income | F46: =F43-F45 -> 11627517 | G46: =G43-G45 -> 35354679 | H46: =H43-H45 -> 6945153 | I46: =I43-I45 -> 1927800 | J46: =J43-J45 -> -5798863
B48: Currency Transaction Adjustments | F48: -2042 | G48: -44054 | H48: -3872 | I48: 262588 | J48: -136700
B49: Unrealized Loss on Securities | F49: 0 | G49: 0 | H49: 1598 | I49: -1598 | J49: 0
B50: Net Comprehensive Income | F50: =F46+SUM(F48:F49) -> 11625475 | G50: =G46+SUM(G48:G49) -> 35310625 | H50: =H46+SUM(H48:H49) -> 6942879 | I50: =I46+SUM(I48:I49) -> 2188790 | J50: =J46+SUM(J48:J49) -> -5935563
B53: Cash Flow Statement
F55: 2021 | G55: =F55+1 -> 2022 | H55: =G55+1 -> 2023 | I55: =H55+1 -> 2024 | J55: =I55+1 -> 2025
...

Sheet Production & Reserves
B2: Production & Reserves
B4: Unit Glossary: | C4: Natural Gas: | E4: Oil: | I4: NGL
C5: Mcf | D5: Thousand Cubic Feet | E5: Bbl | F5: Barrel of Oil | I5: Boe | J5: Barrels of Oil Equivalent
C6: MMcf | D6: Million Cubic Feet | E6: MBbl | F6: Thousand Barrels (1,000)
C7: Bcf | D7: Billion Cubic Feet | E7: MMBbl | F7: Million Barrels (1,000,000)
B10: Production
F12: 2021 | G12: 2022 | H12: 2023 | I12: 2024 | J12: 2025
B13: Production: | C13: Units:
B15: Natural Gas Production (Filing) | C15: MMcf | F15: 10233 | G15: 9503 | H15: 8340 | I15: 6142 | J15: 10001
B16: Multiplier to Mcf | C16: 1000 | F16: =$C$16 -> 1000 | G16: =$C$16 -> 1000 | H16: =$C$16 -> 1000 | I16: =$C$16 -> 1000 | J16: =$C$16 -> 1000
B17: Natural Gas production (Mcf) | C17: Mcf | F17: =F15*F16 -> 10233000 | G17: =G15*G16 -> 9503000 | H17: =H15*H16 -> 8340000 | I17: =I15*I16 -> 6142000 | J17: =J15*J16 -> 10001000
B19: Oil Production (Filing) | C19: MBbl | F19: 25 | G19: 32 | H19: 65 | I19: 187 | J19: 223
B20: Oil Multiplier to Bbl | C20: 1000 | F20: =$C$20 -> 1000 | G20: =$C$20 -> 1000 | H20: =$C$20 -> 1000 | I20: =$C$20 -> 1000 | J20: =$C$20 -> 1000
B21: Oil Production (Bbl) | C21: Bbl | F21: =F19*F20 -> 25000 | G21: =G19*G20 -> 32000 | H21: =H19*H20 -> 65000 | I21: =I19*I20 -> 187000 | J21: =J19*J20 -> 223000
B23: NGL Production (Filing) | C23: Mboe | F23: 29 | G23: 44 | H23: 39 | I23: 69 | J23: 81 | L23: *2021 filing has MBbl not Mboe
B24: NGL Multiplier to Boe | C24: 1000 | F24: =$C$24 -> 1000 | G24: =$C$24 -> 1000 | H24: =$C$24 -> 1000 | I24: =$C$24 -> 1000 | J24: =$C$24 -> 1000
B25: NGL Production (Boe) | F25: =F23*F24 -> 29000 | G25: =G23*G24 -> 44000 | H25: =H23*H24 -> 39000 | I25: =I23*I24 -> 69000 | J25: =J23*J24 -> 81000
B27: Standardized Production:
B29: Natural Gas Production (Boe) | C29: Boe | F29: =F17/6 -> 1705500 | G29: =G17/6 -> 1583833.3 | H29: =H17/6 -> 1390000 | I29: =I17/6 -> 1023666.7 | J29: =J17/6 -> 1666833.3
B30: Oil Production (Boe) | C30: Boe | F30: =F21 -> 25000 | G30: =G21 -> 32000 | H30: =H21 -> 65000 | I30: =I21 -> 187000 | J30: =J21 -> 223000
B31: NGL Production (Boe) | C31: Boe | F31: =F25 -> 29000 | G31: =G25 -> 44000 | H31: =H25 -> 39000 | I31: =I25 -> 69000 | J31: =J25 -> 81000
B32: Total Production (Boe) | C32: Boe | F32: =SUM(F29:F31) -> 1759500 | G32: =SUM(G29:G31) -> 1659833.3 | H32: =SUM(H29:H31) -> 1494000 | I32: =SUM(I29:I31) -> 1279666.7 | J32: =SUM(J29:J31) -> 1970833.3
B33: Total Production (Mboe) | C33: Mboe | F33: =F32/1000 -> 1759.5 | G33: =G32/1000 -> 1659.8333 | H33: =H32/1000 -> 1494 | I33: =I32/1000 -> 1279.6667 | J33: =J32/1000 -> 1970.8333
B34: Boe / day | C34: Boe/d | F34: =F32/365 -> 4820.5479 | G34: =G32/365 -> 4547.4886 | H34: =H32/365 -> 4093.1507 | I34: =I32/365 -> 3505.9361 | J34: =J32/365 -> 5399.5434
B36: Production Mix %:
B37: Gas Production % | C37: % | F37: =F29/F32 -> 0.96930946 | G37: =G29/G32 -> 0.95421227 | H37: =H29/H32 -> 0.93038822 | I37: =I29/I32 -> 0.7999479 | J37: =J29/J32 -> 0.84575053
B38: Oil Production % | C38: % | F38: =F30/F32 -> 0.014208582 | G38: =G30/G32 -> 0.019279044 | H38: =H30/H32 -> 0.043507363 | I38: =I30/I32 -> 0.14613181 | J38: =J30/J32 -> 0.11315011
B39: NGL Production % | C39: % | F39: =F31/F32 -> 0.016481955 | G39: =G31/G32 -> 0.026508686 | H39: =H31/H32 -> 0.026104418 | I39: =I31/I32 -> 0.053920292 | J39: =J31/J32 -> 0.041099366
B41: Production Growth:
B43: Natural Gas Growth % | C43: % | F43: - | G43: =(G29/F29)-1 -> -0.071337829 | H43: =(H29/G29)-1 -> -0.12238241 | I43: =(I29/H29)-1 -> -0.26354916 | J43: =(J29/I29)-1 -> 0.62829697
B44: Oil Growth % | C44: % | F44: - | G44: =(G30/F30)-1 -> 0.28 | H44: =(H30/G30)-1 -> 1.03125 | I44: =(I30/H30)-1 -> 1.8769231 | J44: =(J30/I30)-1 -> 0.19251337
B45: NGL Growth % | C45: % | F45: - | G45: =(G31/F31)-1 -> 0.51724138 | H45: =(H31/G31)-1 -> -0.11363636 | I45: =(I31/H31)-1 -> 0.76923077 | J45: =(J31/I31)-1 -> 0.17391304
B46: Total Boe Growth % | C46: % | F46: - | G46: =(G32/F32)-1 -> -0.05664488 | H46: =(H32/G32)-1 -> -0.099909629 | I46: =(I32/H32)-1 -> -0.14346274 | J46: =(J32/I32)-1 -> 0.54011461
B48: Realized Prices:
B50: Natural Gas Realized Price ($/Mcf) | C50: $/Mcf | F50: ='Historical Financials'!F10/'Production & Reserves'!F17 -> 3.0986206 | G50: ='Historical Financials'!G10/'Production & Reserves'!G17 -> 5.9927111 | H50: ='Historical Financials'!H10/'Production & Reserves'!H17 -> 1.7822799 | I50: ='Historical Financials'!I10/'Production & Reserves'!I17 -> 1.7561166 | J50: ='Historical Financials'!J10/'Production & Reserves'!J17 -> 2.9118534
B51: Oil Realized Price ($/Bbl) | C51: $/Bbl | F51: ='Historical Financials'!F12/'Production & Reserves'!F21 -> 71.05984 | G51: ='Historical Financials'!G12/'Production & Reserves'!G21 -> 99.854156 | H51: ='Historical Financials'!H12/'Production & Reserves'!H21 -> 78.316754 | I51: ='Historical Financials'!I12/'Production & Reserves'!I21 -> 73.426128 | J51: ='Historical Financials'!J12/'Production & Reserves'!J21 -> 61.89917
B52: NGL Realized Price ($/BOE) | C52: $/Boe | F52: ='Historical Financials'!F11/'Production & Reserves'!F25 -> 36.327103 | G52: ='Historical Financials'!G11/'Production & Reserves'!G25 -> 39.389318 | H52: ='Historical Financials'!H11/'Production & Reserves'!H25 -> 25.241487 | I52: ='Historical Financials'!I11/'Production & Reserves'!I25 -> 21.477652 | J52: ='Historical Financials'!J11/'Production & Reserves'!J25 -> 24.43037
B53: Total Revenue / BOE | C53: $/Boe | D53: Hydrocarbons Only | F53: =SUM('Historical Financials'!F10:F12)/'Production & Reserves'!F32 -> 19.629535 | G53: =SUM('Historical Financials'!G10:G12)/'Production & Reserves'!G32 -> 37.279163 | H53: =SUM('Historical Financials'!H10:H12)/'Production & Reserves'!H32 -> 14.015543 | I53: =SUM('Historical Financials'!I10:I12)/'Production & Reserves'!I32 -> 20.316785 | J53: =SUM('Historical Financials'!J10:J12)/'Production & Reserves'!J32 -> 22.78418
B55: Unit Economics:
B57: Total Revenue / Total Boe | C57: $/Boe | D57: Hydrocarbons Only | F57: =F53 -> 19.629535 | G57: =G53 -> 37.279163 | H57: =H53 -> 14.015543 | I57: =I53 -> 20.316785 | J57: =J53 -> 22.78418
...

Sheet Capital Structure
B2: Capital Structure
B5: Equity
B7: Share Price | E7: 5.28 | G7: Market Capitalization | J7: =E7*E11 -> 1.5966709e+08
B8: Most Recent Filing | E8: 2026 Q1 10-Q | G8: Market Capitalization Diluted | J8: =E7*E16 -> 1.6379496e+08
B10: Shares:
B11: Basic Shares Outstanding | E11: 30239980
B12: RSUs / Restricted Shares | E12: 781792
B13: Options Outstanding | E13: 0
B14: Warrants | E14: 0
B15: Convertible Securities | E15: 0 | F15: * Do not double count convertible securities and convertible debt in enterprise value
B16: Fully Diluted Shares | E16: =E11+E12+E13+E14+E15 -> 31021772
B17: Dilution % | E17: =(E16/E11)-1 -> 0.025852927
B21: Debt & Liquidity
B23: Debt: | G23: Cash:
B24: Revolving Credit Facility | E24: 45500000 | G24: Cash & Cash Equivalents | J24: 7912858
B25: Term Loans | E25: 0 | G25: Restricted Cash | J25: 553000
B26: Senior Notes | E26: 0 | G26: Total Cash | J26: =SUM(J24:J25) -> 8465858
B27: Convertible Debt | E27: 0
B28: Other Debt | E28: 0 | G28: Net Debt | J28: =E29-J26 -> 37034142
B29: Total Debt | E29: =SUM(E24:E28) -> 45500000
B32: Enterprise Value
B34: Market Capitalization (Diluted) | E34: =J8 -> 1.6379496e+08 | G34: Enterprise Value | J34: =E34+SUM(E36:E38)-SUM(E40:E41) -> 2.008291e+08
B36: Total Debt | E36: =E29 -> 45500000
B37: Preferred Equity | E37: 0
B38: Minority Interest (Non-Controlling Interest) | E38: 0
B40: Total Cash | E40: =J26 -> 8465858
B41: Short Term Investments | E41: 0

Sheet Debt Schedule
B2: Debt Schedule
B5: Debt Summary
F7: 2021 | G7: 2022 | H7: 2023 | I7: 2024 | J7: 2025
B9: Debt Instruments:
B11: Revolving Credit Facility | F11: 0 | G11: 0 | H11: 0 | I11: 0 | J11: 50500000
B12: Terms Loans | F12: 0 | G12: 0 | H12: 0 | I12: 0 | J12: 0
B13: Senior Notes | F13: 0 | G13: 0 | H13: 0 | I13: 0 | J13: 0
B14: Convertible Debt | F14: 0 | G14: 0 | H14: 0 | I14: 0 | J14: 0
B15: Finance Leases | F15: 0 | G15: 0 | H15: 0 | I15: 0 | J15: 0
B16: Other Debt | F16: 0 | G16: 0 | H16: 0 | I16: 0 | J16: 0
B17: Total Debt | F17: =SUM(F11:F16) -> 0 | G17: =SUM(G11:G16) -> 0 | H17: =SUM(H11:H16) -> 0 | I17: =SUM(I11:I16) -> 0 | J17: =SUM(J11:J16) -> 50500000
B19: Liquidity:
B21: Total Debt | F21: =F17 -> 0 | G21: =G17 -> 0 | H21: =H17 -> 0 | I21: =I17 -> 0 | J21: =J17 -> 50500000
B22: Cash & Cash Equivalents | F22: ='Historical Financials'!F149 -> 26497305 | G22: ='Historical Financials'!G149 -> 45236584 | H22: ='Historical Financials'!H149 -> 13403628 | I22: ='Historical Financials'!I149 -> 6519793 | J22: ='Historical Financials'!J149 -> 8959954
B23: Net Debt | F23: =F21-F22 -> -26497305 | G23: =G21-G22 -> -45236584 | H23: =H21-H22 -> -13403628 | I23: =I21-I22 -> -6519793 | J23: =J21-J22 -> 41540046
B24: Adjusted EBITDA | F24: ='Historical Financials'!F35 -> 26947792 | G24: ='Historical Financials'!G35 -> 53199877 | H24: ='Historical Financials'!H35 -> 14553281 | I24: ='Historical Financials'!I35 -> 15059631 | J24: ='Historical Financials'!J35 -> 27794043
B26: Debt Metrics:
B28: Debt / Adjusted EBITDA | F28: 0 | G28: =G21/G24 -> 0 | H28: =H21/H24 -> 0 | I28: =I21/I24 -> 0 | J28: =J21/J24 -> 1.8169361 | L28: If 100% of adj. EBITDA went to debt payments, it'd take X years to repay.
B29: Net Debt / Adjusted EBITDA | F29: =F23/F24 -> -0.98328297 | G29: =G23/G24 -> -0.8503137 | H29: =H23/H24 -> -0.92100386 | I29: =I23/I24 -> -0.43293179 | J29: =J23/J24 -> 1.4945665 | L29: Negative means net cash company. Not leveraged
B30: Interest Expense | F30: =ABS('Historical Financials'!F39) -> 101382 | G30: =ABS('Historical Financials'!G39) -> 50782 | H30: =ABS('Historical Financials'!H39) -> 80379 | I30: =ABS('Historical Financials'!I39) -> 46400 | J30: =ABS('Historical Financials'!J39) -> 624160 | L30: Annual cost of debt.
B31: Adjusted EBITDA / Interest Expense | F31: =F24/F30 -> 265.8045 | G31: =G24/G30 -> 1047.6129 | H31: =H24/H30 -> 181.05825 | I31: =I24/I30 -> 324.56101 | J31: =J24/J30 -> 44.530318 | L31: How many times over can EBITDA cover interest.
B34: Debt Details
B37: Debt Instrument Type:
E38: Crrent Balance | F38: Interest Rates | G38: Maturity Date
B39: Revolving Credit Facility
B40: Term Loan A
B41: Term Loan B
B42: Senior Note A
B43: Senior Note B
B44: Senior Note C
B45: Convertible Notes
B46: Finance Leases
B47: Total Debt

Sheet Forecast Model
B2: Forcast Model
B4: Scenario | C4: 2
E5: 2026 | F5: =E5+1 -> 2027 | G5: =F5+1 -> 2028 | H5: =G5+1 -> 2029 | I5: =H5+1 -> 2030
B7: Natural Gas Growth %:
B8: Bear | E8: -0.05 | F8: -0.05 | G8: -0.05 | H8: -0.05 | I8: -0.05
B9: Base | E9: 0.05 | F9: =E9-0.01 -> 0.04 | G9: =F9-0.01 -> 0.03 | H9: =G9-0.01 -> 0.02 | I9: =H9-0.01 -> 0.01
B10: Bull | E10: 0.1 | F10: 0.1 | G10: 0.1 | H10: 0.1 | I10: 0.1
B12: Oil Growth %:
B13: Bear | E13: -0.05 | F13: -0.05 | G13: -0.05 | H13: -0.05 | I13: -0.05
B14: Base | E14: 0.05 | F14: =E14-0.01 -> 0.04 | G14: =F14-0.01 -> 0.03 | H14: =G14-0.01 -> 0.02 | I14: =H14-0.01 -> 0.01
B15: Bull | E15: 0.1 | F15: 0.1 | G15: 0.1 | H15: 0.1 | I15: 0.1
B17: NGL Growth %:
B18: Bear | E18: -0.05 | F18: -0.05 | G18: -0.05 | H18: -0.05 | I18: -0.05
B19: Base | E19: 0.05 | F19: =E19-0.01 -> 0.04 | G19: =F19-0.01 -> 0.03 | H19: =G19-0.01 -> 0.02 | I19: =H19-0.01 -> 0.01
B20: Bull | E20: 0.1 | F20: 0.1 | G20: 0.1 | H20: 0.1 | I20: 0.1
B22: Natural Gas ($Mcf):
B23: Bear | E23: 2.5 | F23: 2.5 | G23: 2.5 | H23: 2.5 | I23: 2.5
B24: Base | E24: 3.5 | F24: 3.5 | G24: 3.5 | H24: 3.5 | I24: 3.5
B25: Bull | E25: 5 | F25: 5 | G25: 5 | H25: 5 | I25: 5
B27: Oil ($/Bbl):
B28: Bear | E28: 55 | F28: 55 | G28: 55 | H28: 55 | I28: 55
B29: Base | E29: 70 | F29: 70 | G29: 70 | H29: 70 | I29: 70
B30: Bull | E30: 85 | F30: 85 | G30: 85 | H30: 85 | I30: 85
B32: NGL ($/Bbl):
B33: Bear | E33: 18 | F33: 18 | G33: 18 | H33: 18 | I33: 18
B34: Base | E34: 25 | F34: 25 | G34: 25 | H34: 25 | I34: 25
B35: Bull | E35: 35 | F35: 35 | G35: 35 | H35: 35 | I35: 35
B37: Active Assumption:
B39: Gas Growth % | E39: {=INDEX(E8:E10,$C$4)} -> 0.05 | F39: {=INDEX(F8:F10,$C$4)} -> 0.04 | G39: {=INDEX(G8:G10,$C$4)} -> 0.03 | H39: {=INDEX(H8:H10,$C$4)} -> 0.02 | I39: {=INDEX(I8:I10,$C$4)} -> 0.01
B40: Oil Growth % | E40: {=INDEX(E13:E15,$C$4)} -> 0.05 | F40: {=INDEX(F13:F15,$C$4)} -> 0.04 | G40: {=INDEX(G13:G15,$C$4)} -> 0.03 | H40: {=INDEX(H13:H15,$C$4)} -> 0.02 | I40: {=INDEX(I13:I15,$C$4)} -> 0.01
B41: NGL Growth % | E41: {=INDEX(E18:E20,$C$4)} -> 0.05 | F41: {=INDEX(F18:F20,$C$4)} -> 0.04 | G41: {=INDEX(G18:G20,$C$4)} -> 0.03 | H41: {=INDEX(H18:H20,$C$4)} -> 0.02 | I41: {=INDEX(I18:I20,$C$4)} -> 0.01
B42: Natural Gas Price ($/Mcf) | E42: {=INDEX(E23:E25,$C$4)} -> 3.5 | F42: {=INDEX(F23:F25,$C$4)} -> 3.5 | G42: {=INDEX(G23:G25,$C$4)} -> 3.5 | H42: {=INDEX(H23:H25,$C$4)} -> 3.5 | I42: {=INDEX(I23:I25,$C$4)} -> 3.5
B43: Oil Price ($/Bbl) | E43: {=INDEX(E28:E30,$C$4)} -> 70 | F43: {=INDEX(F28:F30,$C$4)} -> 70 | G43: {=INDEX(G28:G30,$C$4)} -> 70 | H43: {=INDEX(H28:H30,$C$4)} -> 70 | I43: {=INDEX(I28:I30,$C$4)} -> 70
B44: NGL Price ($/Bbl) | E44: {=INDEX(E33:E35,$C$4)} -> 25 | F44: {=INDEX(F33:F35,$C$4)} -> 25 | G44: {=INDEX(G33:G35,$C$4)} -> 25 | H44: {=INDEX(H33:H35,$C$4)} -> 25 | I44: {=INDEX(I33:I35,$C$4)} -> 25
B47: Production Forecast
F49: 2021 | G49: =F49+1 -> 2022 | H49: =G49+1 -> 2023 | I49: =H49+1 -> 2024 | J49: =I49+1 -> 2025 | K49: =J49+1 -> 2026 | L49: =K49+1 -> 2027 | M49: =L49+1 -> 2028 | N49: =M49+1 -> 2029 | O49: =N49+1 -> 2030
B51: Production: | D51: Actuals | E51: Assumptons
B53: Natural Gas Production (Mcf) | F53: ='Production & Reserves'!F17 -> 10233000 | G53: ='Production & Reserves'!G17 -> 9503000 | H53: ='Production & Reserves'!H17 -> 8340000 | I53: ='Production & Reserves'!I17 -> 6142000 | J53: ='Production & Reserves'!J17 -> 10001000 | K53: =J53*(1+K54) -> 10501050 | L53: =K53*(1+L54) -> 10921092 | M53: =L53*(1+M54) -> 11248725 | N53: =M53*(1+N54) -> 11473699 | O53: =N53*(1+O54) -> 11588436
B54: Natural Gas Production Growth % | G54: =(G53/F53)-1 -> -0.071337829 | H54: =(H53/G53)-1 -> -0.12238241 | I54: =(I53/H53)-1 -> -0.26354916 | J54: =(J53/I53)-1 -> 0.62829697 | K54: =E39 -> 0.05 | L54: =F39 -> 0.04 | M54: =G39 -> 0.03 | N54: =H39 -> 0.02 | O54: =I39 -> 0.01
B56: Oil Production (Bbl) | F56: ='Production & Reserves'!F21 -> 25000 | G56: ='Production & Reserves'!G21 -> 32000 | H56: ='Production & Reserves'!H21 -> 65000 | I56: ='Production & Reserves'!I21 -> 187000 | J56: ='Production & Reserves'!J21 -> 223000 | K56: =J56*(1+K57) -> 234150 | L56: =K56*(1+L57) -> 243516 | M56: =L56*(1+M57) -> 250821.48 | N56: =M56*(1+N57) -> 255837.91 | O56: =N56*(1+O57) -> 258396.29
...

Sheet Valuation
B2: NAV & Valuation
B5: Basic NAV Valuation
B7: Reserve Value (PV-10 Approximation) | F7: 210000000 | H7: Net Asset Value / Share | L7: =F13/F15 -> 5.5756279
B9: Cash & Cash Equivalents | F9: ='Capital Structure'!J26 -> 8465858 | H9: Current Share Price | L9: 5.28
B11: Total Debt | F11: ='Capital Structure'!E29 -> 45500000 | H11: Discount (Premium) to NAV | L11: =L7-L9 -> 0.29562792
B13: Net Asset Value (NAV) | F13: =F7+F9-F11 -> 172965858 | H13: Margin of Safety | L13: =(L7-L9)/L7 -> 0.053021457
B15: Diluted Shares Outstanding | F15: ='Capital Structure'!E16 -> 31021772
B18: Enterprise Value and Trading Multiples
B20: Year: | F20: 2026
B21: Share Price | F21: ='Capital Structure'!E7 -> 5.28 | H21: Free Cash Flow | L21: ='Forecast Model'!K177 -> 11528285
B22: Enterprise Value | F22: ='Capital Structure'!J34 -> 2.008291e+08 | H22: Free Cash Flow Yield | L22: =L21/F23 -> 0.070382418
B23: Market Capitalization | F23: ='Capital Structure'!J8 -> 1.6379496e+08
B24: Fully Diluted Shares | F24: ='Capital Structure'!E16 -> 31021772 | H24: Average Daily Production (Boe / Day) | L24: ='Forecast Model'!K62/365 -> 5669.5205
H25: EV / Boe per Day | L25: =F22/L24 -> 35422.589
B26: EBITDA | F26: ='Forecast Model'!K139 -> 35585009
B27: EBITDAX | F27: ='Forecast Model'!K132 -> 37504418 | H27: Proved Reserves (Boe) | L27: ='Production & Reserves'!J88 -> 26006333
B28: EBIT | F28: ='Forecast Model'!K150 -> 22182013 | H28: EV / Proved Boe | L28: =F22/L27 -> 7.722315
B30: EV / EBITDA | F30: =F22/F26 -> 5.6436433 | H30: NAV / Share | L30: =L7 -> 5.5756279
B31: EV / EBITDAX | F31: =F22/F27 -> 5.3548118 | H31: Price / NAV | L31: =F21/L30 -> 0.94697854
B32: EV / EBIT | F32: =F22/F28 -> 9.0536913
B34: EPS | F34: ='Forecast Model'!K159 -> 0.56488683
B35: Forward P / E | F35: =F21/F34 -> 9.347005
B38: Intrinsic Value and Margin of Safety
F40: Bear | G40: Base | H40: Bull
B42: Assumptions:
B43: Oil Price | F43: ='Forecast Model'!E28 -> 55 | G43: ='Forecast Model'!E29 -> 70 | H43: ='Forecast Model'!E30 -> 85
B44: Natural Gas Price | F44: ='Forecast Model'!E23 -> 2.5 | G44: ='Forecast Model'!E24 -> 3.5 | H44: ='Forecast Model'!E25 -> 5
B45: NGL Price | F45: ='Forecast Model'!E33 -> 18 | G45: ='Forecast Model'!E34 -> 25 | H45: ='Forecast Model'!E35 -> 35
B47: Forecasts (2026E):
B48: Production (Boe) | F48: ='Forecast Model'!C195 -> 1872291.7 | G48: ='Forecast Model'!C196 -> 2069375 | H48: ='Forecast Model'!C197 -> 2167916.7
B49: Revenue | F49: ='Forecast Model'!F195 -> 43807147 | G49: ='Forecast Model'!F196 -> 62288347 | H49: ='Forecast Model'!F197 -> 85992422
B50: EBITDAX | F50: ='Forecast Model'!C189 -> 21383592 | G50: ='Forecast Model'!C190 -> 37504418 | H50: ='Forecast Model'!C191 -> 60028306
B51: EBITDA | F51: ='Forecast Model'!F189 -> 19464183 | G51: ='Forecast Model'!F190 -> 35585009 | H51: ='Forecast Model'!F191 -> 58108897
B52: Target EV/EBITDAX | F52: 4.5 | G52: 5.5 | H52: 6.5
B54: Valuation:
B55: Target Enterprise Value | F55: =F50*F52 -> 96226164 | G55: =G50*G52 -> 2.062743e+08 | H55: =H50*H52 -> 3.9018399e+08
B56: Net Debt | F56: ='Capital Structure'!$J$28 -> 37034142 | G56: ='Capital Structure'!$J$28 -> 37034142 | H56: ='Capital Structure'!$J$28 -> 37034142
B57: Target Equity Value | F57: =F55-F56 -> 59192022 | G57: =G55-G56 -> 1.6924016e+08 | H57: =H55-H56 -> 3.5314984e+08
B58: Fully Diluted Share | F58: =('Capital Structure'!$E$16)+200000 -> 31221772 | G58: =('Capital Structure'!$E$16)+200000 -> 31221772 | H58: =('Capital Structure'!$E$16)+200000 -> 31221772
B59: Intrinsic Value / Share | F59: =F57/F58 -> 1.8958572 | G59: =G57/G58 -> 5.4205814 | H59: =H57/H58 -> 11.311012
...
