Workbook

Sheet Historical Financials
B2: Holley Inc.
B5: Income Statement
B7: In thousands | G7: 2020 | H7: =G7+1 -> 2021 | I7: =H7+1 -> 2022 | J7: =I7+1 -> 2023 | K7: =J7+1 -> 2024 | L7: =K7+1 -> 2025 | M7: H12026
B9: Revenue | G9: 504179 | H9: 692847 | I9: 688415 | J9: 659704 | K9: 602224 | L9: 613514 | M9: 319337
B10: COGS | G10: -295935 | H10: -406040 | I10: -434757 | J10: -403615 | K10: -363680 | L10: -347279 | M10: -188057
B11: Gross Profit | G11: =G9+G10 -> 208244 | H11: =H9+H10 -> 286807 | I11: =I9+I10 -> 253658 | J11: =J9+J10 -> 256089 | K11: =K9+K10 -> 238544 | L11: =L9+L10 -> 266235 | M11: =M9+M10 -> 131280
B13: SG&A | G13: -70875 | H13: -116793 | I13: -150728 | J13: -120244 | K13: -132149 | L13: -146132 | M13: -75829
B14: R&D | G14: -23483 | H14: -28280 | I14: -29083 | J14: -23844 | K14: -18710 | L14: -18831 | M14: -7736
B15: Amortization of Intangible Assets | G15: -11082 | H15: -13999 | I15: -14683 | J15: -14557 | K15: -13884 | L15: -13778 | M15: -6844
B16: Impairment of Indefinite-Lived Intangible Assets | G16: 0 | H16: 0 | I16: -2395 | J16: 0 | K16: -7695 | L16: 0 | M16: 0
B17: Impairment of Goodwill | G17: 0 | H17: 0 | I17: 0 | J17: 0 | K17: -40906 | L17: 0 | M17: 0
B18: Acquisition and Restructuyring Costs | G18: -9743 | H18: -23668 | I18: -4513 | J18: -2641 | K18: -1566 | L18: -2903 | M18: -1715
B19: Loss on Sale of Assets | G19: 0 | H19: 0 | I19: 0 | J19: 0 | K19: -9234 | L19: 0 | M19: -28224
B20: Related Party Acquisiton and Management Fee Costs | G20: -6089 | H20: -25789 | I20: 0 | J20: 0 | K20: 0 | L20: 0 | M20: 0
B21: Other Operating Expense | G21: -1517 | H21: -755 | I21: -1514 | J21: -765 | K21: 268 | L21: -2110 | M21: 9341
B22: Total OpEx | G22: =SUM(G13:G21) -> -122789 | H22: =SUM(H13:H21) -> -209284 | I22: =SUM(I13:I21) -> -202916 | J22: =SUM(J13:J21) -> -162051 | K22: =SUM(K13:K21) -> -223876 | L22: =SUM(L13:L21) -> -183754 | M22: =SUM(M13:M21) -> -111007
B23: EBIT | G23: =G11+G22 -> 85455 | H23: =H11+H22 -> 77523 | I23: =I11+I22 -> 50742 | J23: =J11+J22 -> 94038 | K23: =K11+K22 -> 14668 | L23: =L11+L22 -> 82481 | M23: =M11+M22 -> 20273
B25: D&A | G25: =G46+G47 -> 18968 | H25: =H46+H47 -> 25526 | I25: =I46+I47 -> 24790 | J25: =J46+J47 -> 24865 | K25: =K46+K47 -> 24435 | L25: =L46+L47 -> 23482 | M25: =M46+M47 -> 12018
B26: EBITDA | G26: =G23+G25 -> 104423 | H26: =H23+H25 -> 103049 | I26: =I23+I25 -> 75532 | J26: =J23+J25 -> 118903 | K26: =K23+K25 -> 39103 | L26: =L23+L25 -> 105963 | M26: =M23+M25 -> 32291
B28: Amoritzation | G28: =G47 -> 11082 | H28: =H47 -> 13999 | I28: =I47 -> 14683 | J28: =J47 -> 14557 | K28: =K47 -> 13884 | L28: =L47 -> 13778 | M28: =M47 -> 6844
B29: EBITA | G29: =G23+G28 -> 96537 | H29: =H23+H28 -> 91522 | I29: =I23+I28 -> 65425 | J29: =J23+J28 -> 108595 | K29: =K23+K28 -> 28552 | L29: =L23+L28 -> 96259 | M29: =M23+M28 -> 27117
B31: Change in Fair Value of Warrant Liability | G31: 0 | H31: -32580 | I31: 57021 | J31: -4111 | K31: 7570 | L31: -1211 | M31: 1579
B32: Change in Fair Value of Earn-Out Liability | G32: 0 | H32: -8875 | I32: 10731 | J32: -2303 | K32: 2333 | L32: -897 | M32: 1772
B33: Loss On Early Extinguishment of Debt | G33: 0 | H33: -13650 | I33: 0 | J33: 701 | K33: -141 | L33: 93
B34: Interest Expense | G34: -43772 | H34: -39128 | I34: -40227 | J34: -60746 | K34: -50690 | L34: -51833 | M34: -18119
B35: EBT | G35: =G23+SUM(G31:G34) -> 41683 | H35: =H23+SUM(H31:H34) -> -16710 | I35: =I23+SUM(I31:I34) -> 78267 | J35: =J23+SUM(J31:J34) -> 27579 | K35: =K23+SUM(K31:K34) -> -26260 | L35: =L23+SUM(L31:L34) -> 28633 | M35: =M23+SUM(M31:M34) -> 5505
B37: Taxes | G37: -8826 | H37: -10429 | I37: -4493 | J37: -8399 | K37: 3025 | L37: -9458 | M37: -679
B38: Net Income (Loss) | G38: =G35+G37 -> 32857 | H38: =H35+H37 -> -27139 | I38: =I35+I37 -> 73774 | J38: =J35+J37 -> 19180 | K38: =K35+K37 -> -23235 | L38: =L35+L37 -> 19175 | M38: =M35+M37 -> 4826
B41: Cash Flow Statement
B43: In thousands | G43: 2020 | H43: =G43+1 -> 2021 | I43: =H43+1 -> 2022 | J43: =I43+1 -> 2023 | K43: =J43+1 -> 2024 | L43: =K43+1 -> 2025 | M43: H12026
B45: Net Income | G45: =G38 -> 32857 | H45: =H38 -> -27139 | I45: =I38 -> 73774 | J45: =J38 -> 19180 | K45: =K38 -> -23235 | L45: =L38 -> 19175 | M45: =M38 -> 4826
B46: Depreciation | G46: 7886 | H46: 11527 | I46: 10107 | J46: 10308 | K46: 10551 | L46: 9704 | M46: 5174
B47: Amortization of Intangibles | G47: 11082 | H47: 13999 | I47: 14683 | J47: 14557 | K47: 13884 | L47: 13778 | M47: 6844
B48: Other Non-Cash Adjustments | G48: 15872 | H48: 67447 | I48: -29945 | J48: 19206 | K48: 54810 | L48: 35148 | M48: 31303
B50: Working Capital:
B51: AR | G51: -11349 | H51: 464 | I51: 3777 | J51: -2280 | K51: 10756 | L51: -21409 | M51: -2737
B52: Inventory | G52: 22006 | H52: -45073 | I52: -58406 | J52: 38199 | K52: -16557 | L52: -17076 | M52: 13913
B53: Prepaids & Other Assets | G53: 1884 | H53: -13408 | I53: 1142 | J53: 2555 | K53: 2979 | L53: -6181 | M53: -11969
B54: AP | G54: 8399 | H54: 8727 | I54: -740 | J54: -1626 | K54: 1233 | L54: 12861 | M54: -5988
B55: Accrued Interest | G55: 737 | H55: -3229 | I55: 2635 | J55: -5539 | K55: -455 | L55: 115 | M55: 3288
...

Sheet Substack
B2: Holley Inc.
B4: Divisions Reporting
B6: In thousands | G6: 2024 | H6: % | J6: =G6+1 -> 2025 | K6: %
B8: Four Divisions:
B9: American Performance | G9: 389265 | H9: =G9/SUM($G$9:$G$12) -> 0.64637909 | J9: 393929 | K9: =J9/SUM($J$9:$J$12) -> 0.64208641
B10: Euro & Import | G10: 25965 | H10: =G10/SUM($G$9:$G$12) -> 0.043115186 | J10: 29916 | K10: =J10/SUM($J$9:$J$12) -> 0.048761723
B11: Truck & Off-Road | G11: 122069 | H11: =G11/SUM($G$9:$G$12) -> 0.202697 | J11: 125493 | K11: =J11/SUM($J$9:$J$12) -> 0.2045479
B12: Safety & Racing | G12: 64925 | H12: =G12/SUM($G$9:$G$12) -> 0.10780872 | J12: 64176 | K12: =J12/SUM($J$9:$J$12) -> 0.10460397
B13: Total Revenue | G13: =SUM(G9:G12) -> 602224 | H13: =SUM(H9:H12) -> 1 | J13: =SUM(J9:J12) -> 613514 | K13: =SUM(K9:K12) -> 1
B16: Compounder?
B18: Criteria | E18: Holley Today
B19: Decentralization | E19: Partial
B20: EBITA Margins | E20: Mid-Teens
B21: ROIC | E21: ~6.5%
B22: Returns on Capital Employed | E22: High-single digits
B23: Reinvestment Runway | E23: Large
B24: Acquistions Strategy | E24: Improving, unproven
B25: Customer Retention | E25: Hard to measure
B26: Procing Power | E26: Some evidence

Sheet IS Analysis
B2: Income Statement
B4: In thousands | G4: 2020 | H4: 2021 | I4: 2022 | J4: 2023 | K4: 2024 | L4: 2025 | M4: H12026
B6: Revenue | G6: 504179 | H6: 692847 | I6: 688415 | J6: 659704 | K6: 602224 | L6: 613514 | M6: 319337
B7: COGS | G7: -295935 | H7: -406040 | I7: -434757 | J7: -403615 | K7: -363680 | L7: -347279 | M7: -188057
B8: Gross Profit | G8: 208244 | H8: 286807 | I8: 253658 | J8: 256089 | K8: 238544 | L8: 266235 | M8: 131280
B10: SG&A | G10: -70875 | H10: -116793 | I10: -150728 | J10: -120244 | K10: -132149 | L10: -146132 | M10: -75829
B11: R&D | G11: -23483 | H11: -28280 | I11: -29083 | J11: -23844 | K11: -18710 | L11: -18831 | M11: -7736
B12: Amortization of Intangible Assets | G12: -11082 | H12: -13999 | I12: -14683 | J12: -14557 | K12: -13884 | L12: -13778 | M12: -6844
B13: Impairment of Indefinite-Lived Intangible Assets | G13: 0 | H13: 0 | I13: -2395 | J13: 0 | K13: -7695 | L13: 0 | M13: 0
B14: Impairment of Goodwill | G14: 0 | H14: 0 | I14: 0 | J14: 0 | K14: -40906 | L14: 0 | M14: 0
B15: Acquisition and Restructuyring Costs | G15: -9743 | H15: -23668 | I15: -4513 | J15: -2641 | K15: -1566 | L15: -2903 | M15: -1715
B16: Loss on Sale of Assets | G16: 0 | H16: 0 | I16: 0 | J16: 0 | K16: -9234 | L16: 0 | M16: -28224
B17: Related Party Acquisiton and Management Fee Costs | G17: -6089 | H17: -25789 | I17: 0 | J17: 0 | K17: 0 | L17: 0 | M17: 0
B18: Other Operating Expense | G18: -1517 | H18: -755 | I18: -1514 | J18: -765 | K18: 268 | L18: -2110 | M18: 9341
... B22: D&A | G22: 18968 | H22: 25526 | I22: 24790 | J22: 24865 | K22: 24435 | L22: 23482 | M22: 12018
B23: EBITDA | G23: =G20+G22 -> 104423 | H23: =H20+H22 -> 103049 | I23: =I20+I22 -> 75532 | J23: =J20+J22 -> 118903 | K23: =K20+K22 -> 39103 | L23: =L20+L22 -> 105963 | M23: =M20+M22 -> 32291
B25: Change in Fair Value of Warrant Liability | G25: 0 | H25: -32580 | I25: 57021 | J25: -4111 | K25: 7570 | L25: -1211 | M25: 1579
B26: Change in Fair Value of Earn-Out Liability | G26: 0 | H26: -8875 | I26: 10731 | J26: -2303 | K26: 2333 | L26: -897 | M26: 1772
B27: Loss On Early Extinguishment of Debt | G27: 0 | H27: -13650 | I27: 0 | J27: 701 | K27: -141 | L27: 93
B28: Interest Expense | G28: -43772 | H28: -39128 | I28: -40227 | J28: -60746 | K28: -50690 | L28: -51833 | M28: -18119
B29: EBT | G29: 41683 | H29: -16710 | I29: 78267 | J29: 27579 | K29: -26260 | L29: 28633 | M29: 5505
B31: Taxes | G31: -8826 | H31: -10429 | I31: -4493 | J31: -8399 | K31: 3025 | L31: -9458 | M31: -679
B32: Net Income (Loss) | G32: 32857 | H32: -27139 | I32: 73774 | J32: 19180 | K32: -23235 | L32: 19175 | M32: 4826
B35: Growth, Margins
B37: In thousands | G37: 2020 | H37: 2021 | I37: 2022 | J37: 2023 | K37: 2024 | L37: 2025 | M37: H12026
B39: Revenue | G39: =G6 -> 504179 | H39: =H6 -> 692847 | I39: =I6 -> 688415 | J39: =J6 -> 659704 | K39: =K6 -> 602224 | L39: =L6 -> 613514 | M39: =M6 -> 319337
B40: Revenue Growth | H40: =(H6-G6)/G6 -> 0.37420837 | I40: =(I6-H6)/H6 -> -0.0063967947 | J40: =(J6-I6)/I6 -> -0.041705948 | K40: =(K6-J6)/J6 -> -0.087129986 | L40: =(L6-K6)/K6 -> 0.018747177 | M40: =(M6-L6)/L6 -> -0.47949517
B42: COGS Growth | H42: =(H7-G7)/G7 -> 0.37205805 | I42: =(I7-H7)/H7 -> 0.070724559 | J42: =(J7-I7)/I7 -> -0.071630819 | K42: =(K7-J7)/J7 -> -0.0989433 | L42: =(L7-K7)/K7 -> -0.045097338 | M42: =(M7-L7)/L7 -> -0.45848439
B43: Gross Profit Margins | G43: =G8/G6 -> 0.41303585 | H43: =H8/H6 -> 0.41395431 | I43: =I8/I6 -> 0.3684667 | J43: =J8/J6 -> 0.38818773 | K43: =K8/K6 -> 0.3961051 | L43: =L8/L6 -> 0.43395098 | M43: =M8/M6 -> 0.41110175
B45: SG&A (% of Revenue) | G45: =-G10/G39 -> 0.14057507 | H45: =-H10/H39 -> 0.16856968 | I45: =-I10/I39 -> 0.21894933 | J45: =-J10/J39 -> 0.18226962 | K45: =-K10/K39 -> 0.21943496 | L45: =-L10/L39 -> 0.23818853 | M45: =-M10/M39 -> 0.23745761
B46: R&D (% of Revenue) | G46: =-G11/G39 -> 0.046576712 | H46: =-H11/H39 -> 0.040817092 | I46: =-I11/I39 -> 0.042246319 | J46: =-J11/J39 -> 0.036143483 | K46: =-K11/K39 -> 0.031068174 | L46: =-L11/L39 -> 0.030693676 | M46: =-M11/M39 -> 0.024225192
B47: Tax Rate | G47: =-G31/G29 -> 0.211741 | H47: =-H31/H29 -> -0.6241173 | I47: =-I31/I29 -> 0.057406059 | J47: =-J31/J29 -> 0.30454331 | K47: =-K31/K29 -> 0.11519421 | L47: =-L31/L29 -> 0.33031816 | M47: =-M31/M29 -> 0.12334242
B50: Normalized Earnings & Margins
B52: In thousands | G52: 2020 | H52: 2021 | I52: 2022 | J52: 2023 | K52: 2024 | L52: 2025 | M52: H12026
B54: EBIT | G54: =G20 -> 85455 | H54: =H20 -> 77523 | I54: =I20 -> 50742 | J54: =J20 -> 94038 | K54: =K20 -> 14668 | L54: =L20 -> 82481 | M54: =M20 -> 20273
B55: =B13 -> Impairment of Indefinite-Lived Intangible Assets | G55: =G13 -> 0 | H55: =H13 -> 0 | I55: =I13 -> -2395 | J55: =J13 -> 0 | K55: =K13 -> -7695 | L55: =L13 -> 0 | M55: =M13 -> 0
B56: =B14 -> Impairment of Goodwill | G56: =G14 -> 0 | H56: =H14 -> 0 | I56: =I14 -> 0 | J56: =J14 -> 0 | K56: =K14 -> -40906 | L56: =L14 -> 0 | M56: =M14 -> 0
B57: =B15 -> Acquisition and Restructuyring Costs | G57: {=G15:H15} -> -9743 | H57: -23668 | I57: 0 | J57: 0 | K57: 0 | L57: 0 | M57: 0
B58: =B16 -> Loss on Sale of Assets | G58: =G16 -> 0 | H58: =H16 -> 0 | I58: =I16 -> 0 | J58: =J16 -> 0 | K58: =K16 -> -9234 | L58: =L16 -> 0 | M58: =M16 -> -28224
B59: Tarif Refund | G59: 0 | H59: 0 | I59: 0 | J59: 0 | K59: 0 | L59: 0 | M59: 8863
...

Sheet Valuation
B2: Holley Inc.
B4: Valuation EBIT
B6: In thousands | G6: 2025 | H6: =G6+1 -> 2026 | I6: =H6+1 -> 2027 | J6: =I6+1 -> 2028 | K6: =J6+1 -> 2029 | L6: =K6+1 -> 2030
B8: Revenue | G8: ='IS Analysis'!L6 -> 613514 | H8: 610000 | I8: =H8*(1+0.03) -> 628300 | J8: =I8*(1+0.03) -> 647149 | K8: =J8*(1+0.03) -> 666563.47 | L8: =K8*(1+0.03) -> 686560.37
B9: Normalized Operating Margins | G9: ='IS Analysis'!L62 -> 0.13444029 | H9: 0.13 | I9: =H9 -> 0.13 | J9: =I9 -> 0.13 | K9: =J9 -> 0.13 | L9: =K9 -> 0.13
B10: Normalized EBIT | G10: =G8*G9 -> 82481 | H10: =H8*H9 -> 79300 | I10: =I8*I9 -> 81679 | J10: =J8*J9 -> 84129.37 | K10: =K8*K9 -> 86653.251 | L10: =L8*L9 -> 89252.849
B12: Enterprise Value (8x EBIT) | G12: =G10*8 -> 659848 | H12: =H10*8 -> 634400 | I12: =I10*8 -> 653432 | J12: =J10*8 -> 673034.96 | K12: =K10*8 -> 693226.01 | L12: =L10*8 -> 714022.79
B13: Enterprise Value (10x EBIT) | G13: =G10*10 -> 824810 | H13: =H10*10 -> 793000 | I13: =I10*10 -> 816790 | J13: =J10*10 -> 841293.7 | K13: =K10*10 -> 866532.51 | L13: =L10*10 -> 892528.49
B14: Enterprise Value (12x EBIT) | G14: =G10*12 -> 989772 | H14: =H10*12 -> 951600 | I14: =I10*12 -> 980148 | J14: =J10*12 -> 1009552.4 | K14: =K10*12 -> 1039839 | L14: =L10*12 -> 1071034.2
B16: Net Debt | G16: 485418 | H16: =457793-15000 -> 442793 | I16: =H16-30000 -> 412793 | J16: =I16-30000 -> 382793 | K16: =J16-30000 -> 352793 | L16: =K16-30000 -> 322793
B18: Equity Value (8x EBIT) | G18: =G12-G16 -> 174430 | H18: =H12-H16 -> 191607 | I18: =I12-I16 -> 240639 | J18: =J12-J16 -> 290241.96 | K18: =K12-K16 -> 340433.01 | L18: =L12-L16 -> 391229.79
B19: Equity Value (10x EBIT) | G19: =G13-G16 -> 339392 | H19: =H13-H16 -> 350207 | I19: =I13-I16 -> 403997 | J19: =J13-J16 -> 458500.7 | K19: =K13-K16 -> 513739.51 | L19: =L13-L16 -> 569735.49
B20: Equity Value (12x EBIT) | G20: =G14-G16 -> 504354 | H20: =H14-H16 -> 508807 | I20: =I14-I16 -> 567355 | J20: =J14-J16 -> 626759.44 | K20: =K14-K16 -> 687046.01 | L20: =L14-L16 -> 748241.18
B22: Shares Outstanding | G22: 120847 | H22: =G22*(1+0.01) -> 122055.47 | I22: =H22*(1+0.01) -> 123276.02 | J22: =I22*(1+0.01) -> 124508.78 | K22: =J22*(1+0.01) -> 125753.87 | L22: =K22*(1+0.01) -> 127011.41
B24: Per Share (8x EBIT) | G24: =G18/G$22 -> 1.4433954 | H24: =H18/H$22 -> 1.5698354 | I24: =I18/I$22 -> 1.9520341 | J24: =J18/J$22 -> 2.3310962 | K24: =K18/K$22 -> 2.7071374 | L24: =L18/L$22 -> 3.0802727
B25: Per Share (10x EBIT) | G25: =G19/G$22 -> 2.8084437 | H25: =H19/H$22 -> 2.8692446 | I25: =I19/I$22 -> 3.2771741 | J25: =J19/J$22 -> 3.6824767 | K25: =K19/K$22 -> 4.0852778 | L25: =L19/L$22 -> 4.4857031
B26: Per Share (12x EBIT) | G26: =G20/G$22 -> 4.1734921 | H26: =H20/H$22 -> 4.1686538 | I26: =I20/I$22 -> 4.6023142 | J26: =J20/J$22 -> 5.0338572 | K26: =K20/K$22 -> 5.4634183 | L26: =L20/L$22 -> 5.8911335
B28: Model Output | G28: =(G24*0.2)+(G25*0.5)+(G26*0.3) -> 2.9449486 | H28: =(H24*0.2)+(H25*0.5)+(H26*0.3) -> 2.9991855 | I28: =(I24*0.2)+(I25*0.5)+(I26*0.3) -> 3.4096881 | J28: =(J24*0.2)+(J25*0.5)+(J26*0.3) -> 3.8176148 | K28: =(K24*0.2)+(K25*0.5)+(K26*0.3) -> 4.2230919 | L28: =(L24*0.2)+(L25*0.5)+(L26*0.3) -> 4.6262462
B30: Expected Value (10% EBIT Margins) | G30: 2.9449486 | H30: 1.4698809 | I30: 1.8501002 | J30: 2.2271439 | K30: 2.6011266 | L30: 2.9721627
B31: Expected Value (13% EBIT Margins) | G31: 2.9449486 | H31: 2.9991855 | I31: 3.4096881 | J31: 3.8176148 | K31: 4.2230919 | L31: 4.6262462
B32: Expected Value (16% EBIT Margins) | G32: 2.9449486 | H32: 4.5284902 | I32: 4.9692761 | J32: 5.4080856 | K32: 5.8450572 | L32: 6.2803296
B34: Overall EV | G34: =(G30*0.25)+(G31*0.5)+(G32*0.25) -> 2.9449486 | H34: =(H30*0.25)+(H31*0.5)+(H32*0.25) -> 2.9991855 | I34: =(I30*0.25)+(I31*0.5)+(I32*0.25) -> 3.4096881 | J34: =(J30*0.25)+(J31*0.5)+(J32*0.25) -> 3.8176148 | K34: =(K30*0.25)+(K31*0.5)+(K32*0.25) -> 4.2230919 | L34: =(L30*0.25)+(L31*0.5)+(L32*0.25) -> 4.6262462
B35: Current Share Price | G35: 2.6 | H35: 2.6 | I35: 2.6 | J35: 2.6 | K35: 2.6 | L35: 2.6
B36: Implied Upside from Overall EV | G36: =(G34/G35)-1 -> 0.13267253 | H36: =(H34/H35)-1 -> 0.1535329 | I36: =(I34/I35)-1 -> 0.31141852 | J36: =(J34/J35)-1 -> 0.46831337 | K36: =(K34/K35)-1 -> 0.62426611 | L36: =(L34/L35)-1 -> 0.77932545
B39: Holley Inc.
B41: Valuation 18% EBITA margins
B43: In thousands | G43: 2025 | H43: =G43+1 -> 2026 | I43: =H43+1 -> 2027 | J43: =I43+1 -> 2028 | K43: =J43+1 -> 2029 | L43: =K43+1 -> 2030
B45: Revenue | G45: ='IS Analysis'!L6 -> 613514 | H45: 610000 | I45: =H45*(1+0.03) -> 628300 | J45: =I45*(1+0.03) -> 647149 | K45: =J45*(1+0.03) -> 666563.47 | L45: =K45*(1+0.03) -> 686560.37
B46: Normalized EBITA Margins | G46: ='IS Analysis'!L75 -> 0.15689781 | H46: 0.18 | I46: =H46 -> 0.18 | J46: =I46 -> 0.18 | K46: =J46 -> 0.18 | L46: =K46 -> 0.18
B47: Normalized EBITA | G47: =G45*G46 -> 96259 | H47: =H45*H46 -> 109800 | I47: =I45*I46 -> 113094 | J47: =J45*J46 -> 116486.82 | K47: =K45*K46 -> 119981.42 | L47: =L45*L46 -> 123580.87
B49: Enterprise Value (7x EBITA) | G49: =G47*7 -> 673813 | H49: =H47*7 -> 768600 | I49: =I47*7 -> 791658 | J49: =J47*7 -> 815407.74 | K49: =K47*7 -> 839869.97 | L49: =L47*7 -> 865066.07
B50: Enterprise Value (9x EBITA) | G50: =G47*9 -> 866331 | H50: =H47*9 -> 988200 | I50: =I47*9 -> 1017846 | J50: =J47*9 -> 1048381.4 | K50: =K47*9 -> 1079832.8 | L50: =L47*9 -> 1112227.8
B51: Enterprise Value (11x EBITA) | G51: =G47*11 -> 1058849 | H51: =H47*11 -> 1207800 | I51: =I47*11 -> 1244034 | J51: =J47*11 -> 1281355 | K51: =K47*11 -> 1319795.7 | L51: =L47*11 -> 1359389.5
B53: Net Debt | G53: 485418 | H53: =457793-15000 -> 442793 | I53: =H53-30000 -> 412793 | J53: =I53-30000 -> 382793 | K53: =J53-30000 -> 352793 | L53: =K53-30000 -> 322793
B55: Equity Value (7x EBITA) | G55: =G49-G53 -> 188395 | H55: =H49-H53 -> 325807 | I55: =I49-I53 -> 378865 | J55: =J49-J53 -> 432614.74 | K55: =K49-K53 -> 487076.97 | L55: =L49-L53 -> 542273.07
B56: Equity Value (9x EBITA) | G56: =G50-G53 -> 380913 | H56: =H50-H53 -> 545407 | I56: =I50-I53 -> 605053 | J56: =J50-J53 -> 665588.38 | K56: =K50-K53 -> 727039.82 | L56: =L50-L53 -> 789434.81
B57: Equity Value (11x EBITA) | G57: =G51-G53 -> 573431 | H57: =H51-H53 -> 765007 | I57: =I51-I53 -> 831241 | J57: =J51-J53 -> 898562.02 | K57: =K51-K53 -> 967002.67 | L57: =L51-L53 -> 1036596.5
B59: Shares Outstanding | G59: 120847 | H59: =G59*(1+0.01) -> 122055.47 | I59: =H59*(1+0.01) -> 123276.02 | J59: =I59*(1+0.01) -> 124508.78 | K59: =J59*(1+0.01) -> 125753.87 | L59: =K59*(1+0.01) -> 127011.41
B61: Per Share (7x EBITA) | G61: =G55/G$22 -> 1.5589547 | H61: =H55/H$22 -> 2.6693355 | I61: =I55/I$22 -> 3.0733064 | J61: =J55/J$22 -> 3.474572 | K61: =K55/K$22 -> 3.8732562 | L61: =L55/L$22 -> 4.2694831
B62: Per Share (9x EBITA) | G62: =G56/G$22 -> 3.1520269 | H62: =H56/H$22 -> 4.4685175 | I62: =I56/I$22 -> 4.9081158 | J62: =J56/J$22 -> 5.3457142 | K62: =K56/K$22 -> 5.7814507 | L62: =L56/L$22 -> 6.2154636
...

Sheet BS Analysis
B2: Holley Inc.
B5: Balance Sheet
B7: In thousands | G7: 2020 | H7: =G7+1 -> 2021 | I7: =H7+1 -> 2022 | J7: =I7+1 -> 2023 | K7: =J7+1 -> 2024 | L7: =K7+1 -> 2025 | M7: H12026
B9: Cash | G9: 71674 | H9: 36325 | I9: 26150 | J9: 41081 | K9: 56087 | L9: 37231 | M9: 69020
B10: AR | G10: 47341 | H10: 51390 | I10: 47083 | J10: 48360 | K10: 36123 | L10: 57895 | M10: 64158
B11: Inventory | G11: 133928 | H11: 185040 | I11: 233573 | J11: 192260 | K11: 192523 | L11: 205661 | M11: 180202
B12: Prepaids & Other Current Assets | G12: 5037 | H12: 18962 | I12: 18157 | J12: 15665 | K12: 12614 | L12: 15374 | M12: 17231
B13: Total Current Assets | G13: =SUM(G9:G12) -> 257980 | H13: =SUM(H9:H12) -> 291717 | I13: =SUM(I9:I12) -> 324963 | J13: =SUM(J9:J12) -> 297366 | K13: =SUM(K9:K12) -> 297347 | L13: =SUM(L9:L12) -> 316161 | M13: =SUM(M9:M12) -> 330611
B14: PP&E, net | G14: 43729 | H14: 51495 | I14: 52181 | J14: 47206 | K14: 40983 | L14: 45127 | M14: 50174
B15: Goodwill | G15: 359099 | H15: 411383 | I15: 418121 | J15: 419056 | K15: 372340 | L15: 372340 | M15: 370958
B16: Intangibles, net | G16: 404522 | H16: 438461 | I16: 424855 | J16: 410465 | K16: 386676 | L16: 396910 | M16: 369753
B17: Right of Use Assets | G17: 0 | H17: 0 | I17: 29522 | J17: 29250 | K17: 35974 | L17: 33415 | M17: 40872
B18: Total Assets | G18: =SUM(G14:G17)+G13 -> 1065330 | H18: =SUM(H14:H17)+H13 -> 1193056 | I18: =SUM(I14:I17)+I13 -> 1249642 | J18: =SUM(J14:J17)+J13 -> 1203343 | K18: =SUM(K14:K17)+K13 -> 1133320 | L18: =SUM(L14:L17)+L13 -> 1163953 | M18: =SUM(M14:M17)+M13 -> 1162368
B20: AP | G20: 34601 | H20: 45708 | I20: 44948 | J20: 43692 | K20: 44781 | L20: 60121 | M20: 55972
B21: Accrued & Other Current Liabilities | G21: 35292 | H21: 34853 | I21: 43317 | J21: 42129 | K21: 43190 | L21: 48316 | M21: 40553
B22: Accrued Interest | G22: 6588 | H22: 3359 | I22: 5994 | J22: 455 | K22: — | L22: 115 | M22: 3401
B23: Current Portion of Debt | G23: 5528 | H23: 7875 | I23: 7000 | J23: 7461 | K23: 7201 | L23: 6571 | M23: 8207
B24: Total Current Liabilities | G24: =SUM(G20:G23) -> 82009 | H24: =SUM(H20:H23) -> 91795 | I24: =SUM(I20:I23) -> 101259 | J24: =SUM(J20:J23) -> 93737 | K24: =SUM(K20:K23) -> 95172 | L24: =SUM(L20:L23) -> 115123 | M24: =SUM(M20:M23) -> 108133
B25: Long-Term Debt | G25: 669458 | H25: 637673 | I25: 643563 | J25: 576710 | K25: 545385 | L25: 516078 | M25: 518606
B26: Deferred Taxes | G26: 71336 | H26: 70045 | I26: 58390 | J26: 53542 | K26: 37391 | L26: 46540 | M26: 47362
B27: Other Noncurrent Liabilities | G27: 2146 | H27: 89056 | I27: 30440 | J27: 38203 | K27: 34220 | L27: 37287 | M27: 38529
B28: Total Liabilities | G28: =SUM(G25:G27)+G24 -> 824949 | H28: =SUM(H25:H27)+H24 -> 888569 | I28: =SUM(I25:I27)+I24 -> 833652 | J28: =SUM(J25:J27)+J24 -> 762192 | K28: =SUM(K25:K27)+K24 -> 712168 | L28: =SUM(L25:L27)+L24 -> 715028 | M28: =SUM(M25:M27)+M24 -> 712630
B29: Stockholders Equity | G29: 240381 | H29: 304487 | I29: 415990 | J29: 441151 | K29: 421152 | L29: 448925 | M29: 449738
B30: Total L & SE | G30: =G28+G29 -> 1065330 | H30: =H28+H29 -> 1193056 | I30: =I28+I29 -> 1249642 | J30: =J28+J29 -> 1203343 | K30: =K28+K29 -> 1133320 | L30: =L28+L29 -> 1163953 | M30: =M28+M29 -> 1162368
B32: Lease Liabilities | G32: 0 | H32: 0 | I32: 30104 | J32: 30125 | K32: 37200 | L32: 34527 | M32: 42691
B35: Ratios
B37: In thousands | G37: 2020 | H37: =G37+1 -> 2021 | I37: =H37+1 -> 2022 | J37: =I37+1 -> 2023 | K37: =J37+1 -> 2024 | L37: =K37+1 -> 2025 | M37: H12026
B39: Working Capital | G39: =G13-G24 -> 175971 | H39: =H13-H24 -> 199922 | I39: =I13-I24 -> 223704 | J39: =J13-J24 -> 203629 | K39: =K13-K24 -> 202175 | L39: =L13-L24 -> 201038 | M39: =M13-M24 -> 222478
B41: Current Ratio | G41: =G13/G24 -> 3.1457523 | H41: =H13/H24 -> 3.1779182 | I41: =I13/I24 -> 3.2092258 | J41: =J13/J24 -> 3.1723439 | K41: =K13/K24 -> 3.1243118 | L41: =L13/L24 -> 2.7462888 | M41: =M13/M24 -> 3.0574478
B42: Quick Ratio | G42: =(G9+G10)/G24 -> 1.4512432 | H42: =(H9+H10)/H24 -> 0.95555313 | I42: =(I9+I10)/I24 -> 0.7232246 | J42: =(J9+J10)/J24 -> 0.95416964 | K42: =(K9+K10)/K24 -> 0.9688774 | L42: =(L9+L10)/L24 -> 0.82629883 | M42: =(M9+M10)/M24 -> 1.2316129
B44: Total Debt | G44: =G23+G25+G32 -> 674986 | H44: =H23+H25+H32 -> 645548 | I44: =I23+I25+I32 -> 680667 | J44: =J23+J25+J32 -> 614296 | K44: =K23+K25+K32 -> 589786 | L44: =L23+L25+L32 -> 557176 | M44: =M23+M25+M32 -> 569504
B45: Net Debt w/ OpLease | G45: =G44-G9 -> 603312 | H45: =H44-H9 -> 609223 | I45: =I44-I9 -> 654517 | J45: =J44-J9 -> 573215 | K45: =K44-K9 -> 533699 | L45: =L44-L9 -> 519945 | M45: =M44-M9 -> 500484
B46: Net Debt w/o OpLeases | G46: =G45-G32 -> 603312 | H46: =H45-H32 -> 609223 | I46: =I45-I32 -> 624413 | J46: =J45-J32 -> 543090 | K46: =K45-K32 -> 496499 | L46: =L45-L32 -> 485418 | M46: =M45-M32 -> 457793
B47: Net Debt Reduction | H47: =G45-H45 -> -5911 | I47: =H45-I45 -> -45294 | J47: =I45-J45 -> 81302 | K47: =J45-K45 -> 39516 | L47: =K45-L45 -> 13754 | M47: =L45-M45 -> 19461
B49: Debt / Equity | G49: =G44/G29 -> 2.807984 | H49: =H44/H29 -> 2.1201168 | I49: =I44/I29 -> 1.6362581 | J49: =J44/J29 -> 1.3924847 | K49: =K44/K29 -> 1.4004113 | L49: =L44/L29 -> 1.2411338 | M49: =M44/M29 -> 1.2663017
B50: Debt / Assets | G50: =G44/G18 -> 0.63359335 | H50: =H44/H18 -> 0.54108776 | I50: =I44/I18 -> 0.5446896 | J50: =J44/J18 -> 0.51049119 | K50: =K44/K18 -> 0.52040553 | L50: =L44/L18 -> 0.47869287 | M50: =M44/M18 -> 0.48995155
B52: Tangible Book Value | G52: =G29-G15-G16 -> -523240 | H52: =H29-H15-H16 -> -545357 | I52: =I29-I15-I16 -> -426986 | J52: =J29-J15-J16 -> -388370 | K52: =K29-K15-K16 -> -337864 | L52: =L29-L15-L16 -> -320325 | M52: =M29-M15-M16 -> -290973
B53: Book Value | G53: =G29 -> 240381 | H53: =H29 -> 304487 | I53: =I29 -> 415990 | J53: =J29 -> 441151 | K53: =K29 -> 421152 | L53: =L29 -> 448925 | M53: =M29 -> 449738
B55: Googwill & Intangibles (% of Assets) | G55: =(G15+G16)/G18 -> 0.71679292 | H55: =(H15+H16)/H18 -> 0.71232532 | I55: =(I15+I16)/I18 -> 0.674574 | J55: =(J15+J16)/J18 -> 0.68934709 | K55: =(K15+K16)/K18 -> 0.66972788 | L55: =(L15+L16)/L18 -> 0.66089438 | M55: =(M15+M16)/M18 -> 0.63724311
B57: Normalized EBITDA | G57: ='IS Analysis'!G67 -> 120255 | H57: ='IS Analysis'!H67 -> 152506 | I57: ='IS Analysis'!I67 -> 77927 | J57: ='IS Analysis'!J67 -> 118903 | K57: ='IS Analysis'!K67 -> 96938 | L57: ='IS Analysis'!L67 -> 105963 | M57: ='IS Analysis'!M67 -> 51652
...
