Workbook

Sheet Historical Financials
B2: Motorcar Parts of America, Inc.
B5: Income Statement
B7: In thousands | G7: 2021 | H7: =G7+1 -> 2022 | I7: =H7+1 -> 2023 | J7: =I7+1 -> 2024 | K7: =J7+1 -> 2025 | L7: =K7+1 -> 2026 | M7: Q1 2027
B9: Revenue | G9: 540782 | H9: 650308 | I9: 683074 | J9: 717684 | K9: 757354 | L9: 789806 | M9: 168021
B10: COGS | G10: -431321 | H10: =-532443 -> -532443 | I10: -569112 | J10: -585133 | K10: -603526 | L10: -629905 | M10: -140847
B11: Gross Profit | G11: =SUM(G9:G10) -> 109461 | H11: =SUM(H9:H10) -> 117865 | I11: =SUM(I9:I10) -> 113962 | J11: =SUM(J9:J10) -> 132551 | K11: =SUM(K9:K10) -> 153828 | L11: =SUM(L9:L10) -> 159901 | M11: =SUM(M9:M10) -> 27174
B13: Total Operating Expense | G13: -62828 | H13: -89161 | I13: -77516 | J13: -86431 | K13: -113905 | L13: -94066 | M13: -23642
B14: EBIT | G14: =G11+G13 -> 46633 | H14: =H11+H13 -> 28704 | I14: =I11+I13 -> 36446 | J14: =J11+J13 -> 46120 | K14: =K11+K13 -> 39923 | L14: =L11+L13 -> 65835 | M14: =M11+M13 -> 3532
B16: Depreciation | G16: 9573 | H16: 11338 | I16: 10984 | J16: 10544 | K16: 9923 | L16: 9453 | M16: 2742
B17: EBITDA | G17: =G16+G14 -> 56206 | H17: =H16+H14 -> 40042 | I17: =I16+I14 -> 47430 | J17: =J16+J14 -> 56664 | K17: =K16+K14 -> 49846 | L17: =L16+L14 -> 75288 | M17: =M16+M14 -> 6274
B19: Interest Expense | G19: -15770 | H19: -15555 | I19: -39555 | J19: -60040 | K19: -55550 | L19: -46696 | M19: -12044
B20: Total Other Expenses | G20: -15770 | H20: -15555 | I20: -39555 | J20: -59188 | K20: -55610 | L20: -45566 | M20: -13584
B21: EBT | G21: =G14+G20 -> 30863 | H21: =H14+H20 -> 13149 | I21: =I14+I20 -> -3109 | J21: =J14+J20 -> -13068 | K21: =K14+K20 -> -15687 | L21: =L14+L20 -> 20269 | M21: =M14+M20 -> -10052
B23: Taxes | G23: -9387 | H23: -5788 | I23: -1098 | J23: -36176 | K23: -3783 | L23: -7875 | M23: -3369
B24: Net Income | G24: =G23+G21 -> 21476 | H24: =H23+H21 -> 7361 | I24: =I23+I21 -> -4207 | J24: =J23+J21 -> -49244 | K24: =K23+K21 -> -19470 | L24: =L23+L21 -> 12394 | M24: =M23+M21 -> -13421
B27: Cash Flow
B29: In thousands | G29: 2021 | H29: =G29+1 -> 2022 | I29: =H29+1 -> 2023 | J29: =I29+1 -> 2024 | K29: =J29+1 -> 2025 | L29: =K29+1 -> 2026 | M29: Q1 2027
B31: Net Income | G31: =G24 -> 21476 | H31: =H24 -> 7361 | I31: =I24 -> -4207 | J31: =J24 -> -49244 | K31: =K24 -> -19470 | L31: =L24 -> 12394
B32: CFO | G32: 56089 | H32: -44862 | I32: -21754 | J32: 39172 | K32: 45477 | L32: 19158
B33: Change in Working Capital | G33: 9866 | H33: -101225 | I33: -54989 | J33: 16465 | K33: 3930 | L33: -28200
B34: CFO Before Change in WC | G34: =G32-G33 -> 46223 | H34: =H32-H33 -> 56363 | I34: =I32-I33 -> 33235 | J34: =J32-J33 -> 22707 | K34: =K32-K33 -> 41547 | L34: =L32-L33 -> 47358
B36: Capex | G36: -13942 | H36: -7550 | I36: -4201 | J36: -1000 | K36: -4578 | L36: -3696
B37: CFI | G37: -14214 | H37: -7938 | I37: -4191 | J37: -479 | K37: -4469 | L37: -3590
B39: FCF | G39: =G32+G36 -> 42147 | H39: =H32+H36 -> -52412 | I39: =I32+I36 -> -25955 | J39: =J32+J36 -> 38172 | K39: =K32+K36 -> 40899 | L39: =L32+L36 -> 15462
B41: Net Debt Issuance / Repayment | G41: -71750 | H41: 67250 | I41: 18450 | J41: -30325 | K41: -37213 | L41: 3881
B42: Share Repurchases | G42: -1139 | H42: -1914 | I42: 0 | J42: 0 | K42: -4832 | L42: -11351
B43: CFF | G43: -76567 | H43: 60215 | I43: 14308 | J43: -36439 | K43: -44655 | L43: -10980
B45: Net Change in Cash | G45: -34093 | H45: 7493 | I45: -11420 | J45: 2378 | K45: -4545 | L45: 5221
B48: Balance Sheet
B51: In thousands | G51: 2021 | H51: =G51+1 -> 2022 | I51: =H51+1 -> 2023 | J51: =I51+1 -> 2024 | K51: =J51+1 -> 2025 | L51: =K51+1 -> 2026 | M51: Q1 2027
B53: Cash & Cash Equivalent | G53: 15523 | H53: 23016 | I53: 11596 | J53: 13974 | K53: 9429 | L53: 14650 | M53: 19120
B54: Short-Term Investments | G54: 1652 | H54: 2202 | I54: 2011 | J54: 1837 | K54: 1881 | L54: 2028 | M54: 2279
B55: Accounts Receivable | G55: 63122 | H55: 85075 | I55: 119868 | J55: 96296 | K55: 91064 | L55: 112614 | M55: 71362
B56: Inventory | G56: 288361 | H56: 370503 | I56: 339675 | J56: 377040 | K56: 341209 | L56: 380603 | M56: 396858
B57: Inventory Unreturned | G57: 14552 | H57: 15001 | I57: 16579 | J57: 20288 | K57: 18460 | L57: 16438 | M57: 16431
B58: Contract Assets - Current | G58: 26940 | H58: 27500 | I58: 25443 | J58: 27139 | K58: 29606 | L58: 34552 | M58: 35057
B59: Other Current Assets | G59: 12706 | H59: 13688 | I59: 22306 | J59: 23885 | K59: 19822 | L59: 23097 | M59: 23056
B60: Total Current Assets | G60: =SUM(G53:G59) -> 422856 | H60: =SUM(H53:H59) -> 536985 | I60: 537478 | J60: =SUM(J53:J59) -> 560459 | K60: =SUM(K53:K59) -> 511471 | L60: =SUM(L53:L59) -> 583982 | M60: =SUM(M53:M59) -> 564163
B61: PP&E, Net | G61: 53854 | H61: 51062 | I61: 46052 | J61: 38338 | K61: 31990 | L61: 30739 | M61: 29300
B62: Contract Assets - Long Term | G62: 270213 | H62: 310255 | I62: 318381 | J62: 320282 | K62: 336268 | L62: 331221 | M62: 338242
...

Sheet BS Analysis
B2: Balance Sheet
B4: In thousands | G4: 2021 | H4: 2022 | I4: 2023 | J4: 2024 | K4: 2025 | L4: 2026 | M4: Q1 2027
B6: Cash & Cash Equivalent | G6: 15523 | H6: 23016 | I6: 11596 | J6: 13974 | K6: 9429 | L6: 14650 | M6: 19120
B7: Short-Term Investments | G7: 1652 | H7: 2202 | I7: 2011 | J7: 1837 | K7: 1881 | L7: 2028 | M7: 2279
B8: Accounts Receivable | G8: 63122 | H8: 85075 | I8: 119868 | J8: 96296 | K8: 91064 | L8: 112614 | M8: 71362
B9: Inventory | G9: 288361 | H9: 370503 | I9: 339675 | J9: 377040 | K9: 341209 | L9: 380603 | M9: 396858
B10: Inventory Unreturned | G10: 14552 | H10: 15001 | I10: 16579 | J10: 20288 | K10: 18460 | L10: 16438 | M10: 16431
B11: Contract Assets - Current | G11: 26940 | H11: 27500 | I11: 25443 | J11: 27139 | K11: 29606 | L11: 34552 | M11: 35057
B12: Other Current Assets | G12: 12706 | H12: 13688 | I12: 22306 | J12: 23885 | K12: 19822 | L12: 23097 | M12: 23056
B13: Total Current Assets | G13: =SUM(G6:G12) -> 422856 | H13: =SUM(H6:H12) -> 536985 | I13: 537478 | J13: =SUM(J6:J12) -> 560459 | K13: =SUM(K6:K12) -> 511471 | L13: =SUM(L6:L12) -> 583982 | M13: =SUM(M6:M12) -> 564163
B14: PP&E, Net | G14: 53854 | H14: 51062 | I14: 46052 | J14: 38338 | K14: 31990 | L14: 30739 | M14: 29300
B15: Contract Assets - Long Term | G15: 270213 | H15: 310255 | I15: 318381 | J15: 320282 | K15: 336268 | L15: 331221 | M15: 338242
B16: Goodwill & Intangibles | G16: 8534 | H16: 7004 | I16: 5348 | J16: 4274 | K16: 3757 | L16: 3440 | M16: 7355
B17: Total Assets | G17: 847882 | H17: 1015698 | I17: 1028565 | J17: 1012002 | K17: 957636 | L17: 1019437 | M17: 1010024
B19: AP & Accrued Liabilities | G19: 152735 | H19: 168435 | I19: 141766 | J19: 185182 | K19: 172117 | L19: 200499 | M19: 177487
B20: Customer Returns Accrued | G20: 31524 | H20: 38086 | I20: 37984 | J20: 38312 | K20: 34411 | L20: 29923 | M20: 33164
B21: Contract Liabilities - Current | G21: 41072 | H21: 42496 | I21: 40340 | J21: 37591 | K21: 38158 | L21: 61201 | M21: 47570
B22: Revolving Loan | G22: 84000 | H22: 155000 | I22: 145200 | J22: 128000 | K22: 90787 | L22: 94668 | M22: 118839
B23: Current Term Debt | G23: 3678 | H23: 3670 | I23: 3664 | J23: 0 | K23: 0 | L23: 0 | M23: 0
B24: Total Current Liabilities | G24: 326131 | H24: 426405 | I24: 382592 | J24: 404425 | K24: 351025 | L24: 399596 | M24: 391153
B25: Long Term Debt | G25: 16786 | H25: 13024 | I25: 9279 | J25: 0 | K25: 0 | L25: 0 | M25: 0
B26: Convertible Notes | G26: 0 | H26: 0 | I26: 30994 | J26: 30776 | K26: 35207 | L26: 38993 | M26: 44795
... B30: Total Liabilities | G30: 546737 | H30: 700435 | I30: 708090 | J30: 726892 | K30: 699937 | L30: 753427 | M30: 757035
B31: Shareholder's Equity | G31: =G17-G30 -> 301145 | H31: =H17-H30 -> 315263 | I31: =I17-I30 -> 320475 | J31: =J17-J30 -> 285110 | K31: =K17-K30 -> 257699 | L31: =L17-L30 -> 266010 | M31: =M17-M30 -> 252989
B34: Liquidity, Capital
B36: In thousands | G36: 2021 | H36: 2022 | I36: 2023 | J36: 2024 | K36: 2025 | L36: 2026 | M36: Q1 2027
B38: Working Capital | G38: =G13-G24 -> 96725 | H38: =H13-H24 -> 110580 | I38: =I13-I24 -> 154886 | J38: =J13-J24 -> 156034 | K38: =K13-K24 -> 160446 | L38: =L13-L24 -> 184386 | M38: =M13-M24 -> 173010
B39: Current Ratio | G39: =G13/G24 -> 1.2965833 | H39: =H13/H24 -> 1.2593309 | I39: =I13/I24 -> 1.4048333 | J39: =J13/J24 -> 1.3858169 | K39: =K13/K24 -> 1.4570786 | L39: =L13/L24 -> 1.461431 | M39: =M13/M24 -> 1.4423077
B40: Quick Ratio | G40: =(G6+G7+G8)/G24 -> 0.24621088 | H40: =(H6+H7+H8)/H24 -> 0.25865785 | I40: =(I6+I7+I8)/I24 -> 0.34887034 | J40: =(J6+J7+J8)/J24 -> 0.27720096 | K40: =(K6+K7+K8)/K24 -> 0.29164305 | L40: =(L6+L7+L8)/L24 -> 0.32355679 | M40: =(M6+M7+M8)/M24 -> 0.23714761
B41: Net Working Capital | G41: 173262 | H41: 250519 | I41: 296754 | J41: 270859 | K41: 245697 | L41: 266092 | M41: 266092
B44: Net Debt:
B45: Revolving Loan | G45: =G22 -> 84000 | H45: =H22 -> 155000 | I45: =I22 -> 145200 | J45: =J22 -> 128000 | K45: =K22 -> 90787 | L45: =L22 -> 94668 | M45: =M22 -> 118839
B46: Current Term Debt | G46: =G23 -> 3678 | H46: =H23 -> 3670 | I46: =I23 -> 3664 | J46: =J23 -> 0 | K46: =K23 -> 0 | L46: =L23 -> 0 | M46: =M23 -> 0
B47: Long Term Debt | G47: =G25 -> 16786 | H47: =H25 -> 13024 | I47: =I25 -> 9279 | J47: =J25 -> 0 | K47: =K25 -> 0 | L47: =L25 -> 0 | M47: =M25 -> 0
B48: Convertible Notes | G48: =G26 -> 0 | H48: =H26 -> 0 | I48: =I26 -> 30994 | J48: =J26 -> 30776 | K48: =K26 -> 35207 | L48: =L26 -> 38993 | M48: =M26 -> 44795
B49: Operating Lease Liabilities | G49: =G28 -> 76990 | H49: =H28 -> 87591 | I49: =I28 -> 88085 | J49: =J28 -> 80559 | K49: =K28 -> 75290 | L49: =L28 -> 65926 | M49: =M28 -> 65063
B50: Financial Lease Liabilities | G50: =2640+4995 -> 7635 | H50: =2330+3425 -> 5755 | I50: =1851+2742 -> 4593 | J50: =1893+1585 -> 3478 | K50: =1954+1222 -> 3176 | L50: =3202+1289 -> 4491 | M50: =1272+2887 -> 4159
B52: Total Debt & Leases | G52: =SUM(G45:G50) -> 189089 | H52: =SUM(H45:H50) -> 265040 | I52: =SUM(I45:I50) -> 281815 | J52: =SUM(J45:J50) -> 242813 | K52: =SUM(K45:K50) -> 204460 | L52: =SUM(L45:L50) -> 204078 | M52: =SUM(M45:M50) -> 232856
B53: Net Debt | G53: =G52-G6-G7 -> 171914 | H53: =H52-H6-H7 -> 239822 | I53: =I52-I6-I7 -> 268208 | J53: =J52-J6-J7 -> 227002 | K53: =K52-K6-K7 -> 193150 | L53: =L52-L6-L7 -> 187400 | M53: =M52-M6-M7 -> 211457
B54: Net Funded Debt | G54: =SUM(G45:G48)-M6-M7 -> 83065 | H54: =SUM(H45:H48)-N6-N7 -> 171694 | I54: =SUM(I45:I48)-O6-O7 -> 189137 | J54: =SUM(J45:J48)-P6-P7 -> 158776 | K54: =SUM(K45:K48)-Q6-Q7 -> 125994 | L54: =SUM(L45:L48)-R6-R7 -> 133661 | M54: =SUM(M45:M48)-S6-S7 -> 163634
...

Sheet IS Analysis
B2: Motorcar Parts of America, Inc.
B5: Income Statement
B7: In thousands | G7: 2021 | H7: =G7+1 -> 2022 | I7: =H7+1 -> 2023 | J7: =I7+1 -> 2024 | K7: =J7+1 -> 2025 | L7: =K7+1 -> 2026 | M7: Q1 2027
B9: Revenue | G9: 540782 | H9: 650308 | I9: 683074 | J9: 717684 | K9: 757354 | L9: 789806 | M9: 168021
B10: COGS | G10: -431321 | H10: =-532443 -> -532443 | I10: -569112 | J10: -585133 | K10: -603526 | L10: -629905 | M10: -140847
B11: Gross Profit | G11: =SUM(G9:G10) -> 109461 | H11: =SUM(H9:H10) -> 117865 | I11: =SUM(I9:I10) -> 113962 | J11: =SUM(J9:J10) -> 132551 | K11: =SUM(K9:K10) -> 153828 | L11: =SUM(L9:L10) -> 159901 | M11: =SUM(M9:M10) -> 27174
B13: Total Operating Expense | G13: -62828 | H13: -89161 | I13: -77516 | J13: -86431 | K13: -113905 | L13: -94066 | M13: -23642
B14: EBIT | G14: =G11+G13 -> 46633 | H14: =H11+H13 -> 28704 | I14: =I11+I13 -> 36446 | J14: =J11+J13 -> 46120 | K14: =K11+K13 -> 39923 | L14: =L11+L13 -> 65835 | M14: =M11+M13 -> 3532
B16: Depreciation | G16: 9573 | H16: 11338 | I16: 10984 | J16: 10544 | K16: 9923 | L16: 9453 | M16: 2742
B17: EBITDA | G17: =G16+G14 -> 56206 | H17: =H16+H14 -> 40042 | I17: =I16+I14 -> 47430 | J17: =J16+J14 -> 56664 | K17: =K16+K14 -> 49846 | L17: =L16+L14 -> 75288 | M17: =M16+M14 -> 6274
B19: Interest Expense | G19: -15770 | H19: -15555 | I19: -39555 | J19: -60040 | K19: -55550 | L19: -46696 | M19: -12044
B20: Total Other Expenses | G20: -15770 | H20: -15555 | I20: -39555 | J20: -59188 | K20: -55610 | L20: -45566 | M20: -13584
B21: EBT | G21: =G14+G20 -> 30863 | H21: =H14+H20 -> 13149 | I21: =I14+I20 -> -3109 | J21: =J14+J20 -> -13068 | K21: =K14+K20 -> -15687 | L21: =L14+L20 -> 20269 | M21: =M14+M20 -> -10052
B23: Taxes | G23: -9387 | H23: -5788 | I23: -1098 | J23: -36176 | K23: -3783 | L23: -7875 | M23: -3369
B24: Net Income | G24: =G23+G21 -> 21476 | H24: =H23+H21 -> 7361 | I24: =I23+I21 -> -4207 | J24: =J23+J21 -> -49244 | K24: =K23+K21 -> -19470 | L24: =L23+L21 -> 12394 | M24: =M23+M21 -> -13421
B27: Profitability and Margins
B29: In thousands | G29: 2021 | H29: =G29+1 -> 2022 | I29: =H29+1 -> 2023 | J29: =I29+1 -> 2024 | K29: =J29+1 -> 2025 | L29: =K29+1 -> 2026 | M29: Q1 2027
B31: Revenue | G31: =G9 -> 540782 | H31: =H9 -> 650308 | I31: =I9 -> 683074 | J31: =J9 -> 717684 | K31: =K9 -> 757354 | L31: =L9 -> 789806 | M31: =M9 -> 168021
B33: Gross Margin | G33: =G11/G31 -> 0.20241243 | H33: =H11/H31 -> 0.18124489 | I33: =I11/I31 -> 0.16683698 | J33: =J11/J31 -> 0.18469271 | K33: =K11/K31 -> 0.20311242 | L33: =L11/L31 -> 0.20245605 | M33: =M11/M31 -> 0.16172978
B34: Operating Expense (% of Revenue) | G34: =-G13/G31 -> 0.1161799 | H34: =-H13/H31 -> 0.1371058 | I34: =-I13/I31 -> 0.11348112 | J34: =-J13/J31 -> 0.12043044 | K34: =-K13/K31 -> 0.15039862 | L34: =-L13/L31 -> 0.11910013 | M34: =-M13/M31 -> 0.1407086
B35: Operating Margin | G35: =G14/G31 -> 0.08623253 | H35: =H14/H31 -> 0.044139085 | I35: =I14/I31 -> 0.053355859 | J35: =J14/J31 -> 0.064262266 | K35: =K14/K31 -> 0.05271379 | L35: =L14/L31 -> 0.083355913 | M35: =M14/M31 -> 0.021021182
B36: EBITDA Margin | G36: =G17/G31 -> 0.10393467 | H36: =H17/H31 -> 0.0615739 | I36: =I17/I31 -> 0.069436108 | J36: =J17/J31 -> 0.078953969 | K36: =K17/K31 -> 0.065815986 | L36: =L17/L31 -> 0.095324675 | M36: =M17/M31 -> 0.037340571
B39: Adjusted EBIT
B41: In thousands | G41: 2021 | H41: =G41+1 -> 2022 | I41: =H41+1 -> 2023 | J41: =I41+1 -> 2024 | K41: =J41+1 -> 2025 | L41: =K41+1 -> 2026 | M41: Q1 2027
B43: EBIT | G43: =G14 -> 46633 | H43: =H14 -> 28704 | I43: =I14 -> 36446 | J43: =J14 -> 46120 | K43: =K14 -> 39923 | L43: =L14 -> 65835 | M43: =M14 -> 3532
B44: FX Impact | G44: 17606 | H44: 1673 | I44: 9291 | J44: 3814 | K44: -15892 | L44: 8924 | M44: 1597
B45: EBIT (ex -FX) | G45: =G43-G44 -> 29027 | H45: =H43-H44 -> 27031 | I45: =I43-I44 -> 27155 | J45: =J43-J44 -> 42306 | K45: =K43-K44 -> 55815 | L45: =L43-L44 -> 56911 | M45: =M43-M44 -> 1935
B46: EBIT Margin (ex-FX) | G46: =G45/G31 -> 0.053675973 | H46: =H45/H31 -> 0.041566458 | I46: =I45/I31 -> 0.039754112 | J46: =J45/J31 -> 0.058947949 | K46: =K45/K31 -> 0.073697373 | L46: =L45/L31 -> 0.072056936 | M46: =M45/M31 -> 0.011516418
B49: Valuation
B51: In thousands | G51: 2026 | H51: =G51+1 -> 2027 | I51: =H51+1 -> 2028 | J51: =I51+1 -> 2029 | K51: =J51+1 -> 2030 | L51: =K51+1 -> 2031 | M51: =L51+1 -> 2032
B53: Revenue | G53: =L31 -> 789806 | H53: 780000 | I53: 900000 | J53: =I53*(1+0.04) -> 936000 | K53: =J53*(1+0.04) -> 973440 | L53: =K53*(1+0.04) -> 1012377.6 | M53: =L53*(1+0.04) -> 1052872.7
B54: Operating Margins | G54: =L35 -> 0.083355913 | H54: 0.06 | I54: =H54 -> 0.06 | J54: =I54 -> 0.06 | K54: =J54 -> 0.06 | L54: =K54 -> 0.06 | M54: =L54 -> 0.06
B55: Operating Income | G55: =G53*G54 -> 65835 | H55: =H53*H54 -> 46800 | I55: =I53*I54 -> 54000 | J55: =J53*J54 -> 56160 | K55: =K53*K54 -> 58406.4 | L55: =L53*L54 -> 60742.656 | M55: =M53*M54 -> 63172.362
B57: Enterprise Value (10x EBIT) | G57: =G55*10 -> 658350 | H57: =H55*10 -> 468000 | I57: =I55*10 -> 540000 | J57: =J55*10 -> 561600 | K57: =K55*10 -> 584064 | L57: =L55*10 -> 607426.56 | M57: =M55*10 -> 631723.62
B58: Enterprise Value (7.5x EBIT) | G58: =G55*7.5 -> 493762.5 | H58: =H55*7.5 -> 351000 | I58: =I55*7.5 -> 405000 | J58: =J55*7.5 -> 421200 | K58: =K55*7.5 -> 438048 | L58: =L55*7.5 -> 455569.92 | M58: =M55*7.5 -> 473792.72 | P58: =7.5/100 -> 0.075
B59: Enterprise Value (5x EBIT) | G59: =G55*5 -> 329175 | H59: =H55*5 -> 234000 | I59: =I55*5 -> 270000 | J59: =J55*5 -> 280800 | K59: =K55*5 -> 292032 | L59: =L55*5 -> 303713.28 | M59: =M55*5 -> 315861.81
B61: Net Debt | G61: ='BS Analysis'!M54+'BS Analysis'!M50 -> 167793 | H61: =G61 -> 167793 | I61: =H61 -> 167793 | J61: 130000 | K61: =J61 -> 130000 | L61: =K61 -> 130000 | M61: =L61 -> 130000
B63: Equity Value (10x EBIT) | G63: =G57-G61 -> 490557 | H63: =H57-H61 -> 300207 | I63: =I57-I61 -> 372207 | J63: =J57-J61 -> 431600 | K63: =K57-K61 -> 454064 | L63: =L57-L61 -> 477426.56 | M63: =M57-M61 -> 501723.62
B64: Equity Value (7.5x EBIT) | G64: =G58-G61 -> 325969.5 | H64: =H58-H61 -> 183207 | I64: =I58-I61 -> 237207 | J64: =J58-J61 -> 291200 | K64: =K58-K61 -> 308048 | L64: =L58-L61 -> 325569.92 | M64: =M58-M61 -> 343792.72
B65: Equity Value (5x EBIT) | G65: =G59-G61 -> 161382 | H65: =H59-H61 -> 66207 | I65: =I59-I61 -> 102207 | J65: =J59-J61 -> 150800 | K65: =K59-K61 -> 162032 | L65: =L59-L61 -> 173713.28 | M65: =M59-M61 -> 185861.81
...

Sheet Substack Pretty
B2: Motorcar Parts of America, Inc.
B5: Margins and Income
B7: In thousands | G7: 2021 | H7: =G7+1 -> 2022 | I7: =H7+1 -> 2023 | J7: =I7+1 -> 2024 | K7: =J7+1 -> 2025 | L7: =K7+1 -> 2026 | M7: Q1 2027
B9: Revenue | G9: 540782 | H9: 650308 | I9: 683074 | J9: 717684 | K9: 757354 | L9: 789806 | M9: 168021
B10: COGS | G10: -431321 | H10: =-532443 -> -532443 | I10: -569112 | J10: -585133 | K10: -603526 | L10: -629905 | M10: -140847
B11: Gross Profit | G11: =SUM(G9:G10) -> 109461 | H11: =SUM(H9:H10) -> 117865 | I11: =SUM(I9:I10) -> 113962 | J11: =SUM(J9:J10) -> 132551 | K11: =SUM(K9:K10) -> 153828 | L11: =SUM(L9:L10) -> 159901 | M11: =SUM(M9:M10) -> 27174
B12: Gross Profit Margin | G12: =G11/G9 -> 0.20241243 | H12: =H11/H9 -> 0.18124489 | I12: =I11/I9 -> 0.16683698 | J12: =J11/J9 -> 0.18469271 | K12: =K11/K9 -> 0.20311242 | L12: =L11/L9 -> 0.20245605 | M12: =M11/M9 -> 0.16172978
B14: Total Operating Expense | G14: -62828 | H14: -89161 | I14: -77516 | J14: -86431 | K14: -113905 | L14: -94066 | M14: -23642
B15: EBIT | G15: =G11+G14 -> 46633 | H15: =H11+H14 -> 28704 | I15: =I11+I14 -> 36446 | J15: =J11+J14 -> 46120 | K15: =K11+K14 -> 39923 | L15: =L11+L14 -> 65835 | M15: =M11+M14 -> 3532
B16: EBIT Margin | G16: =G15/G9 -> 0.08623253 | H16: =H15/H9 -> 0.044139085 | I16: =I15/I9 -> 0.053355859 | J16: =J15/J9 -> 0.064262266 | K16: =K15/K9 -> 0.05271379 | L16: =L15/L9 -> 0.083355913 | M16: =M15/M9 -> 0.021021182
B18: Depreciation | G18: 9573 | H18: 11338 | I18: 10984 | J18: 10544 | K18: 9923 | L18: 9453 | M18: 2742
B19: EBITDA | G19: =G18+G15 -> 56206 | H19: =H18+H15 -> 40042 | I19: =I18+I15 -> 47430 | J19: =J18+J15 -> 56664 | K19: =K18+K15 -> 49846 | L19: =L18+L15 -> 75288 | M19: =M18+M15 -> 6274
B20: EBITDA Margin | G20: =G19/G9 -> 0.10393467 | H20: =H19/H9 -> 0.0615739 | I20: =I19/I9 -> 0.069436108 | J20: =J19/J9 -> 0.078953969 | K20: =K19/K9 -> 0.065815986 | L20: =L19/L9 -> 0.095324675 | M20: =M19/M9 -> 0.037340571
B23: 10% Operating Margin Valuation
B25: In thousands | G25: 2026 | H25: =G25+1 -> 2027 | I25: =H25+1 -> 2028 | J25: =I25+1 -> 2029 | K25: =J25+1 -> 2030 | L25: =K25+1 -> 2031 | M25: =L25+1 -> 2032
B27: Revenue | G27: ='IS Analysis'!G53 -> 789806 | H27: 780000 | I27: 900000 | J27: =I27*(1+0.04) -> 936000 | K27: =J27*(1+0.04) -> 973440 | L27: =K27*(1+0.04) -> 1012377.6 | M27: =L27*(1+0.04) -> 1052872.7
B28: Operating Margins | G28: 0.083 | H28: 0.06 | I28: =H28 -> 0.06 | J28: =I28 -> 0.06 | K28: =J28 -> 0.06 | L28: =K28 -> 0.06 | M28: =L28 -> 0.06
B29: Operating Income | G29: ='IS Analysis'!G55 -> 65835 | H29: =H27*H28 -> 46800 | I29: =I27*I28 -> 54000 | J29: =J27*J28 -> 56160 | K29: =K27*K28 -> 58406.4 | L29: =L27*L28 -> 60742.656 | M29: =M27*M28 -> 63172.362
B31: Enterprise Value (10x EBIT) | G31: =G29*10 -> 658350 | H31: =H29*10 -> 468000 | I31: =I29*10 -> 540000 | J31: =J29*10 -> 561600 | K31: =K29*10 -> 584064 | L31: =L29*10 -> 607426.56 | M31: =M29*10 -> 631723.62
B32: Enterprise Value (7.5x EBIT) | G32: =G29*7.5 -> 493762.5 | H32: =H29*7.5 -> 351000 | I32: =I29*7.5 -> 405000 | J32: =J29*7.5 -> 421200 | K32: =K29*7.5 -> 438048 | L32: =L29*7.5 -> 455569.92 | M32: =M29*7.5 -> 473792.72
B33: Enterprise Value (5x EBIT) | G33: =G29*5 -> 329175 | H33: =H29*5 -> 234000 | I33: =I29*5 -> 270000 | J33: =J29*5 -> 280800 | K33: =K29*5 -> 292032 | L33: =L29*5 -> 303713.28 | M33: =M29*5 -> 315861.81
B35: Net Debt | G35: ='IS Analysis'!G61 -> 167793 | H35: =G35 -> 167793 | I35: =H35 -> 167793 | J35: 130000 | K35: =J35 -> 130000 | L35: =K35 -> 130000 | M35: =L35 -> 130000
B37: Equity Value (10x EBIT) | G37: =G31-G35 -> 490557 | H37: =H31-H35 -> 300207 | I37: =I31-I35 -> 372207 | J37: =J31-J35 -> 431600 | K37: =K31-K35 -> 454064 | L37: =L31-L35 -> 477426.56 | M37: =M31-M35 -> 501723.62
B38: Equity Value (7.5x EBIT) | G38: =G32-G35 -> 325969.5 | H38: =H32-H35 -> 183207 | I38: =I32-I35 -> 237207 | J38: =J32-J35 -> 291200 | K38: =K32-K35 -> 308048 | L38: =L32-L35 -> 325569.92 | M38: =M32-M35 -> 343792.72
B39: Equity Value (5x EBIT) | G39: =G33-G35 -> 161382 | H39: =H33-H35 -> 66207 | I39: =I33-I35 -> 102207 | J39: =J33-J35 -> 150800 | K39: =K33-K35 -> 162032 | L39: =L33-L35 -> 173713.28 | M39: =M33-M35 -> 185861.81
B41: Shares Outstanding | G41: 18933207 | H41: =G41*(1.01) -> 19122539 | I41: =H41*(1.01) -> 19313764 | J41: =I41*(1.01)+3700000 -> 23206902 | K41: =J41*(1.01) -> 23438971 | L41: =K41*(1.01) -> 23673361 | M41: =L41*(1.01) -> 23910094
B43: Per Share (10x EBIT) | G43: =(G37*1000)/G41 -> 25.909874 | H43: =(H37*1000)/H41 -> 15.699118 | I43: =(I37*1000)/I41 -> 19.271593 | J43: =(J37*1000)/J41 -> 18.597915 | K43: =(K37*1000)/K41 -> 19.372181 | L43: =(L37*1000)/L41 -> 20.167249 | M43: =(M37*1000)/M41 -> 20.983757
B44: Per Share (7.5x EBIT) | G44: =(G38*1000)/G41 -> 17.216814 | H44: =(H38*1000)/H41 -> 9.5806838 | I44: =(I38*1000)/I41 -> 12.281759 | J44: =(J38*1000)/J41 -> 12.547991 | K44: =(K38*1000)/K41 -> 13.142556 | L44: =(L38*1000)/L41 -> 13.752586 | M44: =(M38*1000)/M41 -> 14.37856
B45: Per Share (5x EBIT) | G45: =(G39*1000)/G41 -> 8.5237541 | H45: =(H39*1000)/H41 -> 3.4622494 | I45: =(I39*1000)/I41 -> 5.2919254 | J45: =(J39*1000)/J41 -> 6.4980668 | K45: =(K39*1000)/K41 -> 6.9129314 | L45: =(L39*1000)/L41 -> 7.3379222 | M45: =(M39*1000)/M41 -> 7.7733616
B47: Current Share Price | G47: 10.99 | H47: =G47 -> 10.99 | I47: =H47 -> 10.99 | J47: =I47 -> 10.99 | K47: =J47 -> 10.99 | L47: =K47 -> 10.99 | M47: =L47 -> 10.99
B49: Margin of Safety (10x) | G49: =1-($G$47/G43) -> 0.57583737 | H49: =1-($G$47/H43) -> 0.29996068 | I49: =1-($G$47/I43) -> 0.42973058 | J49: =1-($G$47/J43) -> 0.40907355 | K49: =1-($G$47/K43) -> 0.43269166 | L49: =1-($G$47/L43) -> 0.45505706 | M49: =1-($G$47/M43) -> 0.47626158
B50: Margin of Safety (7.5x) | G50: =1-($G$47/G44) -> 0.36167051 | H50: =1-($G$47/H44) -> -0.14709975 | I50: =1-($G$47/I44) -> 0.10517703 | J50: =1-($G$47/J44) -> 0.12416259 | K50: =1-($G$47/K44) -> 0.16378521 | L50: =1-($G$47/L44) -> 0.20087754 | M50: =1-($G$47/M44) -> 0.23566753
B51: Margin of Safety (5x) | G51: =1-($G$47/G45) -> -0.289338 | H51: =1-($G$47/H45) -> -2.1742369 | I51: =1-($G$47/I45) -> -1.0767489 | J51: =1-($G$47/J45) -> -0.69127224 | K51: =1-($G$47/K45) -> -0.5897742 | L51: =1-($G$47/L45) -> -0.49769917 | M51: =1-($G$47/M45) -> -0.41380274
B53: Expected Value of Shares - Bull (10% EBIT Margin) | G53: =(G43*0.3)+(G44*0.6)+(G45*0.1) -> 18.955426 | H53: =(H43*0.3)+(H44*0.6)+(H45*0.1) -> 10.804371 | I53: =(I43*0.3)+(I44*0.6)+(I45*0.1) -> 13.679726 | J53: =(J43*0.3)+(J44*0.6)+(J45*0.1) -> 13.757976 | K53: =(K43*0.3)+(K44*0.6)+(K45*0.1) -> 14.388481 | L53: =(L43*0.3)+(L44*0.6)+(L45*0.1) -> 15.035518 | M53: =(M43*0.3)+(M44*0.6)+(M45*0.1) -> 15.699599
B56: Expected Value of Shares
B58: In thousands | G58: 2026 | H58: =G58+1 -> 2027 | I58: =H58+1 -> 2028 | J58: =I58+1 -> 2029 | K58: =J58+1 -> 2030 | L58: =K58+1 -> 2031 | M58: =L58+1 -> 2032
B60: Expected Value of Shares - Bear (6% EBIT Margin) | G60: =(G43*0.3)+(G44*0.6)+(G45*0.1) -> 18.955426 | H60: =(H43*0.3)+(H44*0.6)+(H45*0.1) -> 10.804371 | I60: =(I43*0.3)+(I44*0.6)+(I45*0.1) -> 13.679726 | J60: =(J43*0.3)+(J44*0.6)+(J45*0.1) -> 13.757976 | K60: =(K43*0.3)+(K44*0.6)+(K45*0.1) -> 14.388481 | L60: =(L43*0.3)+(L44*0.6)+(L45*0.1) -> 15.035518 | M60: =(M43*0.3)+(M44*0.6)+(M45*0.1) -> 15.699599
B61: Expected Value of Shares - Base (8% EBIT Margin) | G61: 18.96 | H61: 17.548193 | I61: 21.350887 | J61: 20.485543 | K61: 21.305014 | L61: 22.146736 | M61: 23.011391
B62: Expected Value of Shares - Bull (10% EBIT Margin) | G62: 18.96 | H62: 23.857031 | I62: 28.591371 | J62: 26.759582 | K62: 27.772507 | L62: 28.81336 | M62: 29.882992
B64: Overall EV | G64: =(G60*0.25)+(G61*0.5)+(G62*0.25) -> 18.958856 | H64: =(H60*0.25)+(H61*0.5)+(H62*0.25) -> 17.439447 | I64: =(I60*0.25)+(I61*0.5)+(I62*0.25) -> 21.243218 | J64: =(J60*0.25)+(J61*0.5)+(J62*0.25) -> 20.372161 | K64: =(K60*0.25)+(K61*0.5)+(K62*0.25) -> 21.192754 | L64: =(L60*0.25)+(L61*0.5)+(L62*0.25) -> 22.035587 | M64: =(M60*0.25)+(M61*0.5)+(M62*0.25) -> 22.901343
