Workbook

Sheet Historical Financials
B2: Oddity Tech Ltd.
B3: By Deep Value Medici
B6: Income Statement
B9: In thousands | G9: 2021 | H9: 2022 | I9: 2023 | J9: =I9+1 -> 2024 | K9: =J9+1 -> 2025 | L9: Q1 2026 | M9: Q2 2026 | N9: H12026
B11: Revenue | G11: 222555 | H11: 324520 | I11: 508685 | J11: 647040 | K11: 809844 | L11: 197940 | M11: 180517 | N11: =SUM(L11:M11) -> 378457
B12: Cost of Revenue | G12: -69374 | H12: -106470 | I12: -150456 | J12: -178718 | K12: -221138 | L12: -59970 | M12: -56571 | N12: =SUM(L12:M12) -> -116541
B13: Gross Profit | G13: =SUM(G11:G12) -> 153181 | H13: =SUM(H11:H12) -> 218050 | I13: =SUM(I11:I12) -> 358229 | J13: =SUM(J11:J12) -> 468322 | K13: =SUM(K11:K12) -> 588706 | L13: =SUM(L11:L12) -> 137970 | M13: =SUM(M11:M12) -> 123946 | N13: =SUM(L13:M13) -> 261916
N14: =SUM(L14:M14) -> 0
B15: SG&A | G15: -133669 | H15: -190385 | I15: -283911 | J15: -352722 | K15: -469936 | L15: -163460 | M15: -125206 | N15: =SUM(L15:M15) -> -288666
B16: EBIT | G16: =G13+G15 -> 19512 | H16: =H13+H15 -> 27665 | I16: =I13+I15 -> 74318 | J16: =J13+J15 -> 115600 | K16: =K13+K15 -> 118770 | L16: =L13+L15 -> -25490 | M16: =M13+M15 -> -1260 | N16: =SUM(L16:M16) -> -26750
N17: =SUM(L17:M17) -> 0
B18: Depreciation | G18: 4006 | H18: 4408 | I18: 8605 | J18: 9827 | K18: 10687 | L18: 4269 | M18: =N18-L18 -> 3232 | N18: 7501
B19: EBITDA | G19: =G16+G18 -> 23518 | H19: =H16+H18 -> 32073 | I19: =I16+I18 -> 82923 | J19: =J16+J18 -> 125427 | K19: =K16+K18 -> 129457 | L19: =L16+L18 -> -21221 | M19: =M16+M18 -> 1972 | N19: =SUM(L19:M19) -> -19249
N20: =SUM(L20:M20) -> 0
B21: Financial Income, Net | G21: =-877 -> -877 | H21: 1247 | I21: 4283 | J21: 12306 | K21: 16935 | L21: 5306 | M21: 16533 | N21: =SUM(L21:M21) -> 21839
B22: EBT | G22: =G21+G16 -> 18635 | H22: =H21+H16 -> 28912 | I22: =I21+I16 -> 78601 | J22: =J21+J16 -> 127906 | K22: =K21+K16 -> 135705 | L22: =L21+L16 -> -20184 | M22: =M21+M16 -> 15273 | N22: =SUM(L22:M22) -> -4911
N23: =SUM(L23:M23) -> 0
B24: Taxes | G24: -4715 | H24: -7184 | I24: -20067 | J24: -26415 | K24: -24960 | L24: -1177 | M24: -2383 | N24: =SUM(L24:M24) -> -3560
B25: Net Income | G25: =G22+G24 -> 13920 | H25: =H22+H24 -> 21728 | I25: =I22+I24 -> 58534 | J25: =J22+J24 -> 101491 | K25: =K22+K24 -> 110745 | L25: =L22+L24 -> -21361 | M25: =M22+M24 -> 12890 | N25: =SUM(L25:M25) -> -8471
B28: Cash Flow Statement
B31: In thousands | G31: 2021 | H31: 2022 | I31: 2023 | J31: =I31+1 -> 2024 | K31: =J31+1 -> 2025
B33: Net Income | G33: =G25 -> 13920 | H33: =H25 -> 21728 | I33: =I25 -> 58534 | J33: =J25 -> 101491 | K33: =K25 -> 110745
B34: Depreciation & Amortization | G34: =G18 -> 4006 | H34: =H18 -> 4408 | I34: =I18 -> 8605 | J34: =J18 -> 9827 | K34: =K18 -> 10687
B35: Stock Based Comp | G35: 2107 | H35: 6697 | I35: 24111 | J35: 25022 | K35: 33891
B36: Change in Working Capital, net | G36: -9436 | H36: 8429 | I36: -2306 | J36: 6417 | K36: -66115
B37: Cash From Operations | G37: 10224 | H37: 39032 | I37: 87445 | J37: 137764 | K37: 87581
B39: Maintence Capex (PP&E) | G39: -2371 | H39: -2347 | I39: -2101 | J39: -3270 | K39: -3936
B40: Growth Capex (Software & Intangibles) | G40: -3354 | H40: -5051 | I40: -3705 | J40: -6332 | K40: -12250
B41: Acquisitions | G41: -11787 | H41: 0 | I41: -23173 | J41: 0 | K41: 0
B42: Treasury Investments, net | G42: 0 | H42: -18000 | I42: -110012 | J42: 11506 | K42: -250912
B43: Other Investing | G43: -1270 | H43: -382 | I43: -1000 | J43: -552 | K43: -150
B44: Cash From Investing | G44: =SUM(G39:G43) -> -18782 | H44: =SUM(H39:H43) -> -25780 | I44: =SUM(I39:I43) -> -139991 | J44: =SUM(J39:J43) -> 1352 | K44: =SUM(K39:K43) -> -267248
B46: Debt Issued (Repaid) | G46: -318 | H46: -362 | I46: -4313 | J46: 0 | K46: 582456
B47: Equity Issuance | G47: 0 | H47: 116 | I47: 54753 | J47: 18706 | K47: 12242
B48: Share Repurchases | G48: 0 | H48: 0 | I48: 0 | J48: -147283 | K48: 0
B49: Other Financing | G49: 0 | H49: 0 | I49: -1629 | J49: 1278 | K49: -63350
B50: Cash From Financing | G50: =SUM(G46:G49) -> -318 | H50: =SUM(H46:H49) -> -246 | I50: =SUM(I46:I49) -> 48811 | J50: =SUM(J46:J49) -> -127299 | K50: =SUM(K46:K49) -> 531348
B52: Ending Cash Balance | G52: 30889 | H52: 43114 | I52: 38766 | J52: 50347 | K52: 402279
B55: Balance Sheet
B58: In thousands | G58: 2021 | H58: 2022 | I58: 2023 | J58: =I58+1 -> 2024 | K58: =J58+1 -> 2025
...

Sheet IS Analysis
B2: Oddity Tech Ltd.
B3: By Deep Value Medici
B6: Income Statement
B9: In thousands | G9: 2021 | H9: 2022 | I9: 2023 | J9: =I9+1 -> 2024 | K9: =J9+1 -> 2025 | L9: Q1 2026 | M9: Q2 2026 | N9: H12026
B11: Revenue | G11: 222555 | H11: 324520 | I11: 508685 | J11: 647040 | K11: 809844 | L11: 197940 | M11: 180517 | N11: =SUM(L11:M11) -> 378457
B12: Cost of Revenue | G12: -69374 | H12: -106470 | I12: -150456 | J12: -178718 | K12: -221138 | L12: -59970 | M12: -56571 | N12: =SUM(L12:M12) -> -116541
B13: Gross Profit | G13: =SUM(G11:G12) -> 153181 | H13: =SUM(H11:H12) -> 218050 | I13: =SUM(I11:I12) -> 358229 | J13: =SUM(J11:J12) -> 468322 | K13: =SUM(K11:K12) -> 588706 | L13: =SUM(L11:L12) -> 137970 | M13: =SUM(M11:M12) -> 123946 | N13: =SUM(L13:M13) -> 261916
B15: SG&A | G15: -133669 | H15: -190385 | I15: -283911 | J15: -352722 | K15: -469936 | L15: -163460 | M15: -125206 | N15: =SUM(L15:M15) -> -288666
B16: EBIT | G16: =G13+G15 -> 19512 | H16: =H13+H15 -> 27665 | I16: =I13+I15 -> 74318 | J16: =J13+J15 -> 115600 | K16: =K13+K15 -> 118770 | L16: =L13+L15 -> -25490 | M16: =M13+M15 -> -1260 | N16: =SUM(L16:M16) -> -26750
B18: Depreciation | G18: 4006 | H18: 4408 | I18: 8605 | J18: 9827 | K18: 10687 | L18: 4269 | M18: =N18-L18 -> 3232 | N18: 7501
B19: EBITDA | G19: =G16+G18 -> 23518 | H19: =H16+H18 -> 32073 | I19: =I16+I18 -> 82923 | J19: =J16+J18 -> 125427 | K19: =K16+K18 -> 129457 | L19: =L16+L18 -> -21221 | M19: =M16+M18 -> 1972 | N19: =SUM(L19:M19) -> -19249
B21: Financial Income, Net | G21: =-877 -> -877 | H21: 1247 | I21: 4283 | J21: 12306 | K21: 16935 | L21: 5306 | M21: 16533 | N21: =SUM(L21:M21) -> 21839
B22: EBT | G22: =G21+G16 -> 18635 | H22: =H21+H16 -> 28912 | I22: =I21+I16 -> 78601 | J22: =J21+J16 -> 127906 | K22: =K21+K16 -> 135705 | L22: =L21+L16 -> -20184 | M22: =M21+M16 -> 15273 | N22: =SUM(L22:M22) -> -4911
B24: Taxes | G24: -4715 | H24: -7184 | I24: -20067 | J24: -26415 | K24: -24960 | L24: -1177 | M24: -2383 | N24: =SUM(L24:M24) -> -3560
B25: Net Income | G25: =G22+G24 -> 13920 | H25: =H22+H24 -> 21728 | I25: =I22+I24 -> 58534 | J25: =J22+J24 -> 101491 | K25: =K22+K24 -> 110745 | L25: =L22+L24 -> -21361 | M25: =M22+M24 -> 12890 | N25: =SUM(L25:M25) -> -8471
B27: Other Relevant Costs:
B28: Advertising | G28: -63771 | H28: -92048 | I28: -125625 | J28: -164370 | K28: -245741
B31: Revenue, Margin, % of Revenue
G33: 2021 | H33: 2022 | I33: 2023 | J33: =I33+1 -> 2024 | K33: =J33+1 -> 2025 | L33: Q1 2026 | M33: Q2 2026 | N33: H12026
B35: Growth:
B36: Revenue | H36: =(H11-G11)/G11 -> 0.45815641 | I36: =(I11-H11)/H11 -> 0.56749969 | J36: =(J11-I11)/I11 -> 0.27198561 | K36: =(K11-J11)/J11 -> 0.2516135
B37: Gross Profit | H37: =(H13-G13)/G13 -> 0.42347941 | I37: =(I13-H13)/H13 -> 0.64287549 | J37: =(J13-I13)/I13 -> 0.30732576 | K37: =(K13-J13)/J13 -> 0.25705391
B38: EBIT | H38: =(H16-G16)/G16 -> 0.41784543 | I38: =(I16-H16)/H16 -> 1.6863546 | J38: =(J16-I16)/I16 -> 0.55547781 | K38: =(K16-J16)/J16 -> 0.027422145
B39: EBITDA | H39: =(H19-G19)/G19 -> 0.36376393 | I39: =(I19-H19)/H19 -> 1.5854457 | J39: =(J19-I19)/I19 -> 0.5125719 | K39: =(K19-J19)/J19 -> 0.032130243
B40: Net Income | H40: =(H25-G25)/G25 -> 0.56091954 | I40: =(I25-H25)/H25 -> 1.6939433 | J40: =(J25-I25)/I25 -> 0.73388116 | K40: =(K25-J25)/J25 -> 0.091180499
B42: Margins:
B43: Gross Margins | G43: =G13/G11 -> 0.6882838 | H43: =H13/H11 -> 0.67191544 | I43: =I13/I11 -> 0.7042256 | J43: =J13/J11 -> 0.72379142 | K43: =K13/K11 -> 0.72693753 | L43: =L13/L11 -> 0.6970294 | M43: =M13/M11 -> 0.68661677 | N43: =N13/N11 -> 0.69206277
B44: Operating Margin (EBIT Margin) | G44: =G16/G11 -> 0.08767271 | H44: =H16/H11 -> 0.085248983 | I44: =I16/I11 -> 0.14609827 | J44: =J16/J11 -> 0.17865974 | K44: =K16/K11 -> 0.14665787 | L44: =L16/L11 -> -0.1287764 | M44: =M16/M11 -> -0.006979952 | N44: =N16/N11 -> -0.070681742
B45: EBITDA Margin | G45: =G19/G11 -> 0.10567276 | H45: =H19/H11 -> 0.098832121 | I45: =I19/I11 -> 0.16301444 | J45: =J19/J11 -> 0.19384737 | K45: =K19/K11 -> 0.15985424 | L45: =L19/L11 -> -0.10720926 | M45: =M19/M11 -> 0.010924179 | N45: =N19/N11 -> -0.050861789
B47: % of Revenue
B48: Cost of Revenue | G48: =-G12/G11 -> 0.3117162 | H48: =-H12/H11 -> 0.32808456 | I48: =-I12/I11 -> 0.2957744 | J48: =-J12/J11 -> 0.27620858 | K48: =-K12/K11 -> 0.27306247 | L48: =-L12/L11 -> 0.3029706 | M48: =-M12/M11 -> 0.31338323 | N48: =-N12/N11 -> 0.30793723
B49: SG&A | G49: =-G15/G11 -> 0.60061108 | H49: =-H15/H11 -> 0.58666646 | I49: =-I15/I11 -> 0.55812733 | J49: =-J15/J11 -> 0.54513168 | K49: =-K15/K11 -> 0.58027966 | L49: =-L15/L11 -> 0.8258058 | M49: =-M15/M11 -> 0.69359672 | N49: =-N15/N11 -> 0.76274451
B50: Tax Rate | G50: =-G24/G22 -> 0.25301851 | H50: =-H24/H22 -> 0.24847814 | I50: =-I24/I22 -> 0.2553021 | J50: =-J24/J22 -> 0.20651885 | K50: =-K24/K22 -> 0.18392837 | L50: =-L24/L22 -> -0.058313516 | M50: =-M24/M22 -> 0.15602698 | N50: =-N24/N22 -> -0.72490328
B51: Advertising | G51: =G28/G11 -> -0.28654041 | H51: =H28/H11 -> -0.28364354 | I51: =I28/I11 -> -0.2469603 | J51: =J28/J11 -> -0.25403375 | K51: =K28/K11 -> -0.30344239 | L51: =L28/L11 -> 0 | M51: =M28/M11 -> 0 | N51: =N28/N11 -> 0
B55: Capex, FCF
G57: 2021 | H57: 2022 | I57: 2023 | J57: =I57+1 -> 2024 | K57: =J57+1 -> 2025 | L57: Q1 2026 | M57: Q2 2026 | N57: H12026
B59: Cash From Operations | G59: 10224 | H59: 39032 | I59: 87445 | J59: 137764 | K59: 87581
B60: Maintence Capex (PP&E) | G60: -2371 | H60: -2347 | I60: -2101 | J60: -3270 | K60: -3936
B61: Growth Capex (Software & Intangibles) | G61: -3354 | H61: -5051 | I61: -3705 | J61: -6332 | K61: -12250
B62: Free Cash Flow | G62: =SUM(G59:G60) -> 7853 | H62: =SUM(H59:H60) -> 36685 | I62: =SUM(I59:I60) -> 85344 | J62: =SUM(J59:J60) -> 134494 | K62: =SUM(K59:K60) -> 83645
...

Sheet Valuation and Scenario
B2: Income Statements
B4: In thousands | G4: 2021 | H4: 2022 | I4: 2023 | J4: =I4+1 -> 2024 | K4: =J4+1 -> 2025 | L4: Q1 2026 | M4: Q2 2026 | N4: H12026
B6: Revenue | G6: 222555 | H6: 324520 | I6: 508685 | J6: 647040 | K6: 809844 | L6: 197940 | M6: 180517 | N6: =SUM(L6:M6) -> 378457
B7: Cost of Revenue | G7: -69374 | H7: -106470 | I7: -150456 | J7: -178718 | K7: -221138 | L7: -59970 | M7: -56571 | N7: =SUM(L7:M7) -> -116541
B8: Gross Profit | G8: 153181 | H8: 218050 | I8: 358229 | J8: 468322 | K8: 588706 | L8: =SUM(L6:L7) -> 137970 | M8: =SUM(M6:M7) -> 123946 | N8: =SUM(N6:N7) -> 261916
B9: Profit Margin | G9: =G8/G6 -> 0.6882838 | H9: =H8/H6 -> 0.67191544 | I9: =I8/I6 -> 0.7042256 | J9: =J8/J6 -> 0.72379142 | K9: =K8/K6 -> 0.72693753 | L9: =L8/L6 -> 0.6970294 | M9: =M8/M6 -> 0.68661677 | N9: =N8/N6 -> 0.69206277
B11: SG&A | G11: -133669 | H11: -190385 | I11: -283911 | J11: -352722 | K11: -469936 | L11: -163460 | M11: -125206 | N11: =SUM(L11:M11) -> -288666
B12: EBIT | G12: 19512 | H12: 27665 | I12: 74318 | J12: 115600 | K12: 118770 | L12: =L8+L11 -> -25490 | M12: =M8+M11 -> -1260 | N12: =N8+N11 -> -26750
B13: Operating Margin | G13: =G12/G6 -> 0.08767271 | H13: =H12/H6 -> 0.085248983 | I13: =I12/I6 -> 0.14609827 | J13: =J12/J6 -> 0.17865974 | K13: =K12/K6 -> 0.14665787 | L13: =L12/L6 -> -0.1287764 | M13: =M12/M6 -> -0.006979952 | N13: =N12/N6 -> -0.070681742
B15: Depreciation | G15: 4006 | H15: 4408 | I15: 8605 | J15: 9827 | K15: 10687 | L15: 4269 | M15: 3232 | N15: 7501
B16: EBITDA | G16: 23518 | H16: 32073 | I16: 82923 | J16: 125427 | K16: 129457 | L16: =L12+L15 -> -21221 | M16: =M12+M15 -> 1972 | N16: =N12+N15 -> -19249
B17: EBITDA Margin | G17: =G16/G6 -> 0.10567276 | H17: =H16/H6 -> 0.098832121 | I17: =I16/I6 -> 0.16301444 | J17: =J16/J6 -> 0.19384737 | K17: =K16/K6 -> 0.15985424 | L17: =L16/L6 -> -0.10720926 | M17: =M16/M6 -> 0.010924179 | N17: =N16/N6 -> -0.050861789
B19: Other Relevant Costs:
B20: Advertising | G20: -63771 | H20: -92048 | I20: -125625 | J20: -164370 | K20: -245741 | L20: =L21*L11 -> -89903
B21: % of SG&A | G21: =G20/G11 -> 0.47708145 | H21: =H20/H11 -> 0.48348347 | I21: =I20/I11 -> 0.44248021 | J21: =J20/J11 -> 0.46600439 | K21: =K20/K11 -> 0.5229244 | L21: 0.55
B23: Financial Income, Net | G23: -877 | H23: 1247 | I23: 4283 | J23: 12306 | K23: 16935 | L23: 5306 | M23: 16533 | N23: 21839
B24: EBT | G24: 18635 | H24: 28912 | I24: 78601 | J24: 127906 | K24: 135705 | L24: =L12+L23 -> -20184 | M24: =M12+M23 -> 15273 | N24: =N12+N23 -> -4911
B26: Taxes | G26: -4715 | H26: -7184 | I26: -20067 | J26: -26415 | K26: -24960 | L26: -1177 | M26: -2383 | N26: -3560
B27: Net Income | G27: 13920 | H27: 21728 | I27: 58534 | J27: 101491 | K27: 110745 | L27: =L24+L26 -> -21361 | M27: =M24+M26 -> 12890 | N27: =N24+N26 -> -8471
B29: Other Relevant Costs:
B30: Advertising | G30: -63771 | H30: -92048 | I30: -125625 | J30: -164370 | K30: -245741 | L30: =L11*L31 -> -89903 | M30: =M11*M31 -> -68863.3 | N30: =N11*N31 -> -158766.3
B31: % of SG&A | G31: =G30/G11 -> 0.47708145 | H31: =H30/H11 -> 0.48348347 | I31: =I30/I11 -> 0.44248021 | J31: =J30/J11 -> 0.46600439 | K31: =K30/K11 -> 0.5229244 | L31: 0.55 | M31: 0.55 | N31: 0.55
B34: Advertising
B36: In thousands | G36: 2021 | H36: 2022 | I36: 2023 | J36: 2024 | K36: 2025 | L36: Q1 2026A
B38: Revenue | G38: 222555 | H38: 324520 | I38: 508685 | J38: 647040 | K38: 809844 | L38: 197940
B40: Other Relevant Costs:
B41: Advertising | G41: -63771 | H41: -92048 | I41: -125625 | J41: -164370 | K41: -245741 | L41: -89903
B42: % of SG&A | G42: 0.47708145 | H42: 0.48348347 | I42: 0.44248021 | J42: 0.46600439 | K42: 0.5229244 | L42: 0.55
B43: % of Revenue | G43: =-G41/G38 -> 0.28654041 | H43: =-H41/H38 -> 0.28364354 | I43: =-I41/I38 -> 0.2469603 | J43: =-J41/J38 -> 0.25403375 | K43: =-K41/K38 -> 0.30344239 | L43: =-L41/L38 -> 0.45419319
B46: 2028 Valuation w/ Different CAC Scenarios
B48: In thousands | G48: Delayed Fix | I48: Partial Normalization | K48: Full Normalization
B50: Revenue | G50: 550000 | I50: 650000 | K50: 700000
B51: Operating Margin | G51: 0.08 | I51: 0.13 | K51: 0.16
B52: EBIT | G52: =G50*G51 -> 44000 | I52: =I50*I51 -> 84500 | K52: =K50*K51 -> 112000
B54: EV / EBIT | G54: 10 | I54: 12.5 | K54: 12.5
B56: Enterprise Value | G56: =G52*G54 -> 440000 | I56: =I52*I54 -> 1056250 | K56: =K52*K54 -> 1400000
B57: Net Cash | G57: 0 | I57: 0 | K57: 0
B58: Equity Value | G58: =G56+G57 -> 440000 | I58: =I56+I57 -> 1056250 | K58: =K56+K57 -> 1400000
B60: Shares | G60: 56000 | I60: 56000 | K60: 56000
B61: Implied Price | G61: =G58/G60 -> 7.8571429 | I61: =I58/I60 -> 18.861607 | K61: =K58/K60 -> 25
...

Sheet BS Analysis 
B2: Balance Sheet
B4: In thousands | G4: 2021 | H4: 2022 | I4: 2023 | J4: =I4+1 -> 2024 | K4: =J4+1 -> 2025 | L4: Q1 2026 | M4: Q2 2026
B6: Cash & Equivalents | G6: X | H6: 40955 | I6: 36538 | J6: 50340 | K6: 402209 | L6: 278597 | M6: 167274
B7: Short-Term Deposits | G7: X | H7: 18000 | I7: 78000 | J7: 48000 | K7: 0 | N7: - Not all Securities Current Asset
B8: Marketable Securities | G8: X | H8: 0 | I8: 1108 | J8: 1880 | K8: 11170 | L8: 17113 | M8: 25880
B9: Accounts Receivable | G9: X | H9: 7576 | I9: 9916 | J9: 9188 | K9: 16902 | L9: 23313 | M9: 12129
B10: Inventory | G10: X | H10: 70230 | I10: 84106 | J10: 99810 | K10: 135181 | L10: 147976 | M10: 152170
B11: Other Current Assets | G11: X | H11: 9172 | I11: 14144 | J11: 14151 | K11: 36336 | L11: 33089 | M11: 33218
B12: Total Current Assets | G12: X | H12: =SUM(H6:H11) -> 145933 | I12: =SUM(I6:I11) -> 223812 | J12: =SUM(J6:J11) -> 223369 | K12: =SUM(K6:K11) -> 601798 | L12: =SUM(L6:L11) -> 500088 | M12: =SUM(M6:M11) -> 390671
B14: Marketable Securities | G14: X | H14: 0 | I14: 50507 | J14: 68831 | K14: 362571 | L14: 371626 | M14: 368008
B15: PP&E | G15: X | H15: 9468 | I15: 9245 | J15: 9817 | K15: 10864 | L15: 9986 | M15: 10044
B16: Intangible Assets | G16: X | H16: 26800 | I16: 36001 | J16: 36458 | K16: 43582 | L16: 46141 | M16: 48462
B17: Goodwill | G17: X | H17: 16237 | I17: 64904 | J17: 64904 | K17: 64904 | L17: 64904 | M17: 64904
B18: Deferred Tax Assets | G18: X | H18: 2334 | I18: 3924 | J18: 8786 | K18: 27693 | L18: 30299 | M18: 28811
B19: Other Long-Term Assets | G19: X | H19: 15636 | I19: 16513 | J19: 26717 | K19: 26380 | L19: =22701+4082 -> 26783 | M19: =19918+4305 -> 24223
B20: Total Assets | G20: X | H20: =SUM(H12:H19) -> 216408 | I20: =SUM(I12:I19) -> 404906 | J20: =SUM(J12:J19) -> 438882 | K20: =SUM(K12:K19) -> 1137792 | L20: =SUM(L12:L19) -> 1049827 | M20: =SUM(M12:M19) -> 935123
B22: Accounts Payable | G22: X | H22: 44807 | I22: 56185 | J22: 79130 | K22: 75957 | L22: 65252 | M22: 63076
B23: Accrued Liabilities | G23: X | H23: 37792 | I23: 49325 | J23: 38566 | K23: 32869 | L23: 51374 | M23: 44347
B24: Debt | G24: X | H24: 4565 | I24: 0 | J24: 0 | K24: 584368 | L24: 585222 | M24: 537246
B25: Lease Liabilities | G25: X | H25: 11966 | I25: 12514 | J25: 22710 | K25: 23465 | L25: =6537+17260 -> 23797 | M25: =5764+16231 -> 21995
B26: Other Liabilities | G26: X | H26: 6298 | I26: 3775 | J26: 16172 | K26: 24638 | L26: 25272 | M26: 25187
B27: Total Liabilities | G27: X | H27: =SUM(H22:H26) -> 105428 | I27: =SUM(I22:I26) -> 121799 | J27: =SUM(J22:J26) -> 156578 | K27: =SUM(K22:K26) -> 741297 | L27: =SUM(L22:L26) -> 750917 | M27: =SUM(M22:M26) -> 691851
B29: Additional Paid-In Capital | G29: X | H29: 53707 | I29: 178910 | J29: 76912 | K29: 77571 | L29: 4230 | M29: -65340
B30: Retained Earnings | G30: X | H30: 43244 | I30: 101778 | J30: 203269 | K30: 314014 | L30: 292653 | M30: 305543
B31: AOCI | G31: X | H31: 1738 | I31: 2402 | J31: 2106 | K31: 4892 | L31: 2011 | M31: 3055
B32: Total Equity | G32: X | H32: 98705 | I32: 283107 | J32: 282304 | K32: 396495 | L32: 298910 | M32: 243272
B34: Total Liabilities and Equity | G34: X | H34: =H27+H32 -> 204133 | I34: =I27+I32 -> 404906 | J34: =J27+J32 -> 438882 | K34: =K27+K32 -> 1137792 | L34: =L27+L32 -> 1049827 | M34: =M27+M32 -> 935123
B37: Liquidity
G39: 2021 | H39: 2022 | I39: 2023 | J39: =I39+1 -> 2024 | K39: =J39+1 -> 2025 | L39: Q1 2026 | M39: Q2 2026
B41: Cash | G41: X | H41: =H6 -> 40955 | I41: =I6 -> 36538 | J41: =J6 -> 50340 | K41: =K6 -> 402209 | L41: =L6 -> 278597 | M41: =M6 -> 167274
B42: Short-Term Deposits | G42: X | H42: =H7 -> 18000 | I42: =I7 -> 78000 | J42: =J7 -> 48000 | K42: =K7 -> 0 | L42: =L7 -> 0 | M42: =M7 -> 0
B43: Marketable Securities, short term | G43: =G6 -> X | H43: =H8 -> 0 | I43: =I8 -> 1108 | J43: =J8 -> 1880 | K43: =K8 -> 11170 | L43: =L8 -> 17113 | M43: =M8 -> 25880
B44: Marketable Securities, long term | G44: =G7 -> X | H44: =H14 -> 0 | I44: =I14 -> 50507 | J44: =J14 -> 68831 | K44: =K14 -> 362571 | L44: =L14 -> 371626 | M44: =M14 -> 368008
B45: Total Liquid Assets | G45: X | H45: =SUM(H41:H44) -> 58955 | I45: =SUM(I41:I44) -> 166153 | J45: =SUM(J41:J44) -> 169051 | K45: =SUM(K41:K44) -> 775950 | L45: =SUM(L41:L44) -> 667336 | M45: =SUM(M41:M44) -> 561162 | O45: =L45-M45 -> 106174
B47: Current Assets | G47: X | H47: =H12 -> 145933 | I47: =I12 -> 223812 | J47: =J12 -> 223369 | K47: =K12 -> 601798 | L47: =L12 -> 500088 | M47: =M12 -> 390671
B48: Current Liabilities | G48: X | H48: 90406 | I48: 109312 | J48: 124802 | K48: 114828 | L48: 123163 | M48: 113187
B49: Current Ratio | G49: X | H49: =H47/H48 -> 1.614196 | I49: =I47/I48 -> 2.0474605 | J49: =J47/J48 -> 1.789787 | K49: =K47/K48 -> 5.2408646 | L49: =L47/L48 -> 4.0603753 | M49: =M47/M48 -> 3.4515536
B51: Net Debt (Cash) | G51: X | H51: =H24-H6 -> -36390 | I51: =I24-I6 -> -36538 | J51: =J24-J6 -> -50340 | K51: =K24-K6 -> 182159 | L51: =L24-L6 -> 306625 | M51: =M24-M6 -> 369972
B52: Net Debt (Liquid Assets) | G52: X | H52: =H24-H45 -> -54390 | I52: =I24-I45 -> -166153 | J52: =J24-J45 -> -169051 | K52: =K24-K45 -> -191582 | L52: =L24-L45 -> -82114 | M52: =M24-M45 -> -23916
B55: Capital Structure
...
